<?xml version="1.0" encoding="utf-8"?>
<mujoco model="MyoLegExo">
    <include file="myo_sim/leg/assets/myolegs_chain.xml"/>
    <include file ="myo_sim/leg/assets/myolegs_assets.xml"/>
    <compiler angle="radian" autolimits="true"/>
    <option timestep="0.001"/>
    <size nconmax="100" njmax="500" nkey="1" nuser_jnt="1"/>

    <default>
        <joint limited="true"/>
        <equality solimp="0.9 0.95 0.001 0.4 2" solref="0.02 1"/>
        <default class="multi_mode_controlled_actuator">
         <general biastype="affine" gainprm="35 0 0 0 0 0 0 0 0 0" biasprm="0 -35 -0.65 0 0 0 0 0 0 0"/>
        </default>
        <tendon rgba="0.95 0.3 0.3 1"/>
    </default>

   <option gravity="0 0 0" integrator="Euler" iterations="5" ls_iterations="20" solver="Newton" 
        timestep="0.001"/>
    
   <visual>
        <headlight ambient="0.5         0.5         0.5" diffuse="0.50 0.50 0.50" specular="0.50 0.50 0.50"/>
        <map force="0.005"/>
        <rgba contactforce="0.7 0.9 0.9 0.5"/>
   </visual>

   <asset>
      <mesh file="amber_sim/models/exo/STL/PelvisLink.STL" name="PelvisLink"/>
      <mesh file="amber_sim/models/exo/STL/LeftFrontalHipLink.STL" name="LeftFrontalHipLink"/>
      <mesh file="amber_sim/models/exo/STL/LeftTransverseHipLink.STL" name="LeftTransverseHipLink"/>
      <mesh file="amber_sim/models/exo/STL/LeftSagittalHipLink.STL" name="LeftSagittalHipLink"/>
      <mesh file="amber_sim/models/exo/STL/LeftSagittalKneeLink.STL" name="LeftSagittalKneeLink"/>
      <mesh file="amber_sim/models/exo/STL/LeftSagittalAnkleLink.STL" name="LeftSagittalAnkleLink"/>
      <mesh file="amber_sim/models/exo/STL/LeftHenkeAnkleLink.STL" name="LeftHenkeAnkleLink"/>
      <mesh file="amber_sim/models/exo/STL/RightFrontalHipLink.STL" name="RightFrontalHipLink"/>
      <mesh file="amber_sim/models/exo/STL/RightTransverseHipLink.STL" name="RightTransverseHipLink"/>
      <mesh file="amber_sim/models/exo/STL/RightSagittalHipLink.STL" name="RightSagittalHipLink"/>
      <mesh file="amber_sim/models/exo/STL/RightSagittalKneeLink.STL" name="RightSagittalKneeLink"/>
      <mesh file="amber_sim/models/exo/STL/RightSagittalAnkleLink.STL" name="RightSagittalAnkleLink"/>
      <mesh file="amber_sim/models/exo/STL/RightHenkeAnkleLink.STL" name="RightHenkeAnkleLink"/>
      <material name="mat1" specular="0.3" shininess="1"/>
      <texture builtin="checker" height="512" name="plane" rgb1="0.9 0.9 0.9"
               rgb2="0.7 0.7 0.7"
               type="2d"
               width="512"/>
      <texture builtin="flat" height="1278" mark="cross" markrgb="1 1 1" name="texgeom" random="0.01" rgb1="0.8 0.6 0.4" rgb2="0.8 0.6 0.4" type="cube" width="127"/>
      <texture builtin="checker" height="100" name="texplane" rgb1="0 0 0" rgb2="0.8 0.8 0.8" type="2d" width="100"/>
      <material name="plane" reflectance="0.5" shininess="1" specular="1" texrepeat="60 60" texture="texplane"/>
      <hfield name="terrain" size="7 7 1 0.001" nrow="100" ncol="100"/>   
   </asset>


   <worldbody>
      <body name="pelvis" pos="0 0 1" quat="0.707107 0.707107 0 0" childclass="myolegs">>
        <site name ="pelvislocation" pos="0 0 0"/>
        <site name="pelvis" class="myo_leg_marker"/>
        <inertial pos="-0.07 -0.03 0" mass="10.96" diaginertia="0.0622075 0.0532711 0.0299242" />
        <freejoint name="mroot"/>
        <geom mesh="r_pelvis" name="r_pelvis" type="mesh"/>
        <geom mesh="l_pelvis" name="l_pelvis" type="mesh"/>
        <geom mesh="sacrum" name="sacrum" type="mesh"/>
        <geom name="Gmax1_at_pelvis_r_wrap" pos="-0.077 -0.099 0.061" quat="0.931256 -0.288071 0.213142 -0.0659324" class="wrap" size="0.04 0.075"/>
        <geom name="Gmax2_at_pelvis_r_wrap" pos="-0.08 -0.083 0.068" quat="0.912872 -0.359331 0.180301 -0.0709714" class="wrap" size="0.04 0.05"/>
        <geom name="Gmax3_at_pelvis_r_wrap" pos="-0.083 -0.088 0.068" quat="0.99875 -0.0499792 0 0" class="wrap" size="0.04 0.05"/>
        <geom name="Gmax1_at_pelvis_l_wrap" pos="-0.077 -0.099 -0.061" quat="0.931256 0.288071 -0.213142 -0.0659324" class="wrap" size="0.04 0.075"/>
        <geom name="Gmax2_at_pelvis_l_wrap" pos="-0.08 -0.083 -0.068" quat="0.912872 0.359331 -0.180301 -0.0709714" class="wrap" size="0.04 0.05"/>
        <geom name="Gmax3_at_pelvis_l_wrap" pos="-0.083 -0.088 -0.068" quat="0.99875 0.0499792 0 0" class="wrap" size="0.04 0.05"/>
        <geom name="PS_at_brim_r_wrap" pos="-0.074 -0.06 0.0656" quat="0.981103 -0.13006 -0.127199 0.0658971" class="wrap" size="0.05" type="sphere"/>
        <geom name="PS_at_brim_l_wrap" pos="-0.074 -0.06 -0.0656" quat="0.981103 0.13006 0.127199 0.0658971" class="wrap" size="0.05" type="sphere"/>
        <geom name="IL_at_brim_r_wrap" pos="-0.071 -0.065 0.0756" quat="0.874257 -0.193832 -0.0376181 0.443495" class="wrap" size="0.0549" type="sphere"/>
        <geom name="IL_at_brim_l_wrap" pos="-0.071 -0.065 -0.0756" quat="0.874257 0.193832 0.0376181 0.443495" class="wrap" size="0.0549" type="sphere"/>
        <site name="addbrev_r-P1" pos="-0.0191 -0.094 0.0154"/>
        <site name="addlong_r-P1" pos="-0.0076 -0.0889 0.0189"/>
        <site name="addmagDist_r-P1" pos="-0.074 -0.1277 0.0398"/>
        <site name="addmagIsch_r-P1" pos="-0.0896 -0.1298 0.0417"/>
        <site name="addmagMid_r-P1" pos="-0.0527 -0.1208 0.0285"/>
        <site name="addmagProx_r-P1" pos="-0.031 -0.1076 0.0136"/>
        <site name="bflh_r-P1" pos="-0.104 -0.1191 0.0586"/>
        <site name="glmax1_r-P1" pos="-0.1231 0.0345 0.0563"/>
        <site name="glmax1_r-P2" pos="-0.1257 -0.0242 0.0779"/>
        <site name="glmax2_r-P1" pos="-0.1317 0.0087 0.0462"/>
        <site name="glmax2_r-P2" pos="-0.1344 -0.0609 0.0813"/>
        <site name="glmax3_r-P1" pos="-0.13 -0.0525 0.009"/>
        <site name="glmax3_r-P2" pos="-0.1273 -0.1263 0.0435"/>
        <site name="glmed1_r-P1" pos="-0.0445 0.0245 0.1172"/>
        <site name="glmed2_r-P1" pos="-0.085 0.0316 0.0675"/>
        <site name="glmed3_r-P1" pos="-0.1152 -0.0073 0.0526"/>
        <site name="glmin1_r-P1" pos="-0.0464 -0.0149 0.1042"/>
        <site name="glmin2_r-P1" pos="-0.0616 -0.0142 0.0971"/>
        <site name="glmin3_r-P1" pos="-0.0789 -0.0155 0.0798"/>
        <site name="grac_r-P1" pos="-0.0474 -0.1293 0.0246"/>
        <site name="iliacus_r-P1" pos="-0.0605 0.0309 0.0843"/>
        <site name="iliacus_r-P2" pos="-0.0135 -0.0557 0.0756"/>
        <site name="piri_r-P1" pos="-0.1018 -0.0065 0.0135"/>
        <site name="piri_r-P2" pos="-0.102 -0.0307 0.0609"/>
        <site name="psoas_r-P1" pos="-0.0606 0.062 0.039"/>
        <site name="psoas_r-P2" pos="-0.0205 -0.0654 0.0656"/>
        <site name="recfem_r-P1" pos="-0.024 -0.0388 0.0933"/>
        <site name="sart_r-P1" pos="-0.0195 -0.0156 0.1056"/>
        <site name="semimem_r-P1" pos="-0.0987 -0.114 0.0614"/>
        <site name="semiten_r-P1" pos="-0.1038 -0.1253 0.0515"/>
        <site name="tfl_r-P1" pos="-0.0311 0.0214 0.1241"/>
        <site name="addbrev_l-P1" pos="-0.0191 -0.094 -0.0154"/>
        <site name="addlong_l-P1" pos="-0.0076 -0.0889 -0.0189"/>
        <site name="addmagDist_l-P1" pos="-0.074 -0.1277 -0.0398"/>
        <site name="addmagIsch_l-P1" pos="-0.0896 -0.1298 -0.0417"/>
        <site name="addmagMid_l-P1" pos="-0.0527 -0.1208 -0.0285"/>
        <site name="addmagProx_l-P1" pos="-0.031 -0.1076 -0.0136"/>
        <site name="bflh_l-P1" pos="-0.104 -0.1191 -0.0586"/>
        <site name="glmax1_l-P1" pos="-0.1231 0.0345 -0.0563"/>
        <site name="glmax1_l-P2" pos="-0.1257 -0.0242 -0.0779"/>
        <site name="glmax2_l-P1" pos="-0.1317 0.0087 -0.0462"/>
        <site name="glmax2_l-P2" pos="-0.1344 -0.0609 -0.0813"/>
        <site name="glmax3_l-P1" pos="-0.13 -0.0525 -0.009"/>
        <site name="glmax3_l-P2" pos="-0.1273 -0.1263 -0.0435"/>
        <site name="glmed1_l-P1" pos="-0.0445 0.0245 -0.1172"/>
        <site name="glmed2_l-P1" pos="-0.085 0.0316 -0.0675"/>
        <site name="glmed3_l-P1" pos="-0.1152 -0.0073 -0.0526"/>
        <site name="glmin1_l-P1" pos="-0.0464 -0.0149 -0.1042"/>
        <site name="glmin2_l-P1" pos="-0.0616 -0.0142 -0.0971"/>
        <site name="glmin3_l-P1" pos="-0.0789 -0.0155 -0.0798"/>
        <site name="grac_l-P1" pos="-0.0474 -0.1293 -0.0246"/>
        <site name="iliacus_l-P1" pos="-0.0605 0.0309 -0.0843"/>
        <site name="iliacus_l-P2" pos="-0.0135 -0.0557 -0.0756"/>
        <site name="piri_l-P1" pos="-0.1018 -0.0065 -0.0135"/>
        <site name="piri_l-P2" pos="-0.102 -0.0307 -0.0609"/>
        <site name="psoas_l-P1" pos="-0.0606 0.062 -0.039"/>
        <site name="psoas_l-P2" pos="-0.0205 -0.0654 -0.0656"/>
        <site name="recfem_l-P1" pos="-0.024 -0.0388 -0.0933"/>
        <site name="sart_l-P1" pos="-0.0195 -0.0156 -0.1056"/>
        <site name="semimem_l-P1" pos="-0.0987 -0.114 -0.0614"/>
        <site name="semiten_l-P1" pos="-0.1038 -0.1253 -0.0515"/>
        <site name="tfl_l-P1" pos="-0.0311 0.0214 -0.1241"/>
        <site name="RASI" pos="0.0095 0.0181 0.1285"/>
        <site name="LASI" pos="0.0095 0.0181 -0.1285"/>
        <site name="RPSI" pos="-0.155 0.035 0.045"/>
        <site name="LPSI" pos="-0.155 0.035 -0.045"/>
        <site name="Gmax1_at_pelvis_r_site_glmax1_r_side" pos="-0.0929654 -0.0868446 0.124923"/>
        <site name="Gmax2_at_pelvis_r_site_glmax2_r_side" pos="-0.13018 -0.1232159 0.1219181"/>
        <site name="Gmax3_at_pelvis_r_site_glmax3_r_side" pos="-0.0530013 -0.127251 0.0521302"/>
        <site name="Gmax1_at_pelvis_l_site_glmax1_l_side" pos="-0.0929654 -0.0868446 -0.124923"/>
        <site name="Gmax2_at_pelvis_l_site_glmax2_l_side" pos="-0.13018 -0.1232159 -0.1219181"/>
        <site name="Gmax3_at_pelvis_l_site_glmax3_l_side" pos="-0.0530013 -0.127251 -0.0521302"/>
        <site name="PS_at_brim_r_site_psoas_r_side" pos="-0.0209166 -0.0856869 0.0790765"/>
        <site name="PS_at_brim_l_site_psoas_l_side" pos="-0.0209166 -0.0856869 -0.0790765"/>
        <site name="IL_at_brim_r_site_iliacus_r_side" pos="-0.02526034 -0.0256276 0.0928915"/>
        <site name="IL_at_brim_l_site_iliacus_l_side" pos="-0.00526034 -0.0756276 -0.0828915"/>
        <body name="femur_r" pos="-0.056276 -0.07849 0.07726">
            <site name ="hip_r_location" pos="0 0 0"/>
            <site name="hip_r" class="myo_leg_marker"/>
            <inertial pos="0 -0.195 -0.0005" quat="0.708013 -0.7062 0 0" mass="8.4" diaginertia="0.1694 0.1694 0.0245269" />
            <joint axis="0 0 1" name="hip_flexion_r" pos="0 0 0" range="-0.523599 2.0944"/>
            <joint axis="1 0 0" name="hip_adduction_r" pos="0 0 0" range="-0.872665 0.523599"/>
            <joint axis="0 1 0" name="hip_rotation_r" pos="0 0 0" range="-0.698132 0.698132"/>
            <!-- <geom name="r_femur1_col" size=".080" class="coll" fromto="0 0 .02 0 -0.2 .015" mass="4"/>
            <geom name="r_femur2_col" size=".067" class="coll" fromto="0 -0.2 .015 0 -0.39 .005" mass="2"/> -->
            <geom mesh="r_femur" name="r_femur" type="mesh"/>
            <geom name="Gastroc_at_condyles_r_wrap" pos="0.005 -0.41 0" class="wrap" size="0.025 0.05"/>
            <geom name="KnExt_at_fem_r_wrap" pos="0.00358828 -0.402732 0.00209111" quat="0.999192 -0.0311532 0.025365 -0.00079084" class="wrap" size="0.025 0.05"/>
            <geom name="AB_at_femshaft_r_wrap" pos="0.0146434 -0.112595 0.023365" quat="0.671362 0.735248 0.0628354 0.0688147" class="wrap" size="0.0165 0.035"/>
            <geom name="AL_at_femshaft_r_wrap" pos="0.0307327 -0.231909 0.0151137" quat="0.629067 0.774355 0.0429971 0.0529276" class="wrap" size="0.0201 0.05"/>
            <geom name="AMprox_at_femshaft_r_wrap" pos="0.00518299 -0.0728948 0.025403" quat="0.689646 0.718132 0.0645174 0.0671823" class="wrap" size="0.0211 0.035"/>
            <geom name="AMmid_at_femshaft_r_wrap" pos="0.0230125 -0.160711 0.0205842" quat="0.690996 0.719631 0.0472547 0.0492129" class="wrap" size="0.0214 0.06"/>
            <geom name="AMdist_at_femshaft_r_wrap" pos="0.0316065 -0.260736 0.0093646" quat="0.652657 0.751902 0.061082 0.0703703" class="wrap" size="0.0218 0.1"/>
            <geom name="AMisch_at_condyles_r_wrap" pos="-0.0226511 -0.376831 -0.00315437" quat="0.638263 0.734777 -0.150578 -0.173347" class="wrap" size="0.04 0.12"/>
            <geom name="PECT_at_femshaft_r_wrap" pos="0.00608573 -0.0845029 0.0304405" quat="0.610649 0.779832 0.0849157 0.108442" class="wrap" size="0.015 0.025"/>
            <site name="addbrev_r-P2" pos="-0.002 -0.118 0.0249"/>
            <site name="addlong_r-P2" pos="0.0113 -0.2394 0.0158"/>
            <site name="addmagDist_r-P2" pos="0.0112 -0.2625 0.0193"/>
            <site name="addmagIsch_r-P2" pos="0.0048 -0.388 -0.0327"/>
            <site name="addmagMid_r-P2" pos="0.0024 -0.1624 0.0292"/>
            <site name="addmagProx_r-P2" pos="-0.0153 -0.0789 0.032"/>
            <site name="bfsh_r-P1" pos="0.005 -0.2111 0.0234"/>
            <site name="gaslat_r-P1" pos="-0.003 -0.3814 0.0277"/>
            <site name="gasmed_r-P1" pos="0.008 -0.3788 -0.0208"/>
            <site name="glmax1_r-P3" pos="-0.0444 -0.0326 0.0302"/>
            <site name="glmax1_r-P4" pos="-0.0277 -0.0566 0.047"/>
            <site name="glmax2_r-P3" pos="-0.045 -0.0584 0.0252"/>
            <site name="glmax2_r-P4" pos="-0.0156 -0.1016 0.0419"/>
            <site name="glmax3_r-P3" pos="-0.0281 -0.1125 0.0094"/>
            <site name="glmax3_r-P4" pos="-0.006 -0.1419 0.0411"/>
            <site name="glmed1_r-P2" pos="-0.0218 -0.0117 0.0555"/>
            <site name="glmed2_r-P2" pos="-0.0258 -0.0058 0.0527"/>
            <site name="glmed3_r-P2" pos="-0.0309 -0.0047 0.0518"/>
            <site name="glmin1_r-P2" pos="-0.0072 -0.0104 0.056"/>
            <site name="glmin2_r-P2" pos="-0.0096 -0.0104 0.056"/>
            <site name="glmin3_r-P2" pos="-0.0135 -0.0083 0.055"/>
            <site name="iliacus_r-P3" pos="-0.0023 -0.0565 0.0139"/>
            <site name="iliacus_r-P4" pos="-0.0122 -0.0637 0.0196"/>
            <site name="piri_r-P3" pos="-0.0148 -0.0036 0.0437"/>
            <site name="psoas_r-P3" pos="-0.0132 -0.0467 0.0046"/>
            <site name="psoas_r-P4" pos="-0.0235 -0.0524 0.0088"/>
            <site name="sart_r-P2" pos="-0.003 -0.3568 -0.0421"/>
            <site name="tfl_r-P2" pos="0.0294 -0.0995 0.0597"/>
            <site name="tfl_r-P3" pos="0.0107 -0.405 0.0324"/>
            <site name="vasint_r-P1" pos="0.029 -0.1924 0.031"/>
            <site name="vasint_r-P2" pos="0.0335 -0.2084 0.0285"/>
            <site name="vaslat_r-P1" pos="0.0048 -0.1854 0.0349"/>
            <site name="vaslat_r-P2" pos="0.0269 -0.2591 0.0409"/>
            <site name="vasmed_r-P1" pos="0.014 -0.2099 0.0188"/>
            <site name="vasmed_r-P2" pos="0.0356 -0.2769 0.0009"/>
            <site name="RHJC" pos="0 0 0"/>
            <site name="RTH1" pos="0.018 -0.15 0.064"/>
            <site name="RTH2" pos="0.08 -0.23 0.0047"/>
            <site name="RTH3" pos="0.01 -0.3 0.06"/>
            <site name="RLFC" pos="0 -0.404 0.05"/>
            <site name="RMFC" pos="0 -0.404 -0.05"/>
            <site name="KnExt_at_fem_r_site_recfem_r_side" pos="0.028412 -0.418795 -0.0326861"/>
            <site name="KnExt_at_fem_r_site_vasint_r_side" pos="0.0140493 -0.375075 -0.00469312"/>
            <site name="KnExt_at_fem_r_site_vaslat_r_side" pos="0.0164816 -0.378983 -0.0366504"/>
            <site name="KnExt_at_fem_r_site_vasmed_r_side" pos="0.0179815 -0.374402 0.023524"/>
            <site name="AB_at_femshaft_r_site_addbrev_r_side" pos="-0.00249969 -0.126567 0.0261656"/>
            <site name="AL_at_femshaft_r_site_addlong_r_side" pos="0.0113183 -0.263228 0.00405212"/>
            <site name="AMprox_at_femshaft_r_site_addmagProx_r_side" pos="-0.0232677 -0.056978 0.0222299"/>
            <site name="AMmid_at_femshaft_r_site_addmagMid_r_side" pos="-0.0100694 -0.108641 0.0230602"/>
            <site name="AMdist_at_femshaft_r_site_addmagDist_r_side" pos="0.0146959 -0.298529 0.0158276"/>
            <site name="AMisch_at_condyles_r_site_addmagIsch_r_side" pos="-0.0360341 -0.49032 -0.0446456"/>
            <body name="tibia_r" pos="-4.6e-07 -0.404425 -0.00126526">
                <site name="knee_r_location" pos="0 0 0"/>
                <site name="knee_r" class="myo_leg_marker"/>
                <inertial pos="-0.005 -0.175 0.0025" quat="0.70204 -0.711847 0.0203385 0" mass="3.8" diaginertia="0.0771589 0.0771589 0.00690387" />
                <joint axis="0.992246 0.123982 -0.00878916" name="knee_angle_r_translation2" pos="0 0 0" range="7.69254e-11 0.006792" type="slide"/>
                <joint axis="-0.124293 0.989762 -0.0701648" name="knee_angle_r_translation1" pos="0 0 0" range="9.53733e-08 0.00159883" type="slide"/>
                <joint axis="-3.98373e-10 -0.0707131 -0.997497" name="knee_angle_r" pos="0 0 0" range="0 2.0944"/>
                <joint axis="0.992246 0.123982 -0.00878916" name="knee_angle_r_rotation2" pos="0 0 0" range="-0.00167821 0.0335354"/>
                <joint axis="-0.124293 0.989762 -0.0701648" name="knee_angle_r_rotation3" pos="0 0 0" range="1.08939e-08 0.262788"/>
                <!-- <geom name="r_tibia1_col" size=".056" class="coll" fromto="0 0 0 -0.01 -0.14 .0025" mass="3.8"/> 14cms -->
                <!-- <geom name="r_tibia2_col" size=".048" class="coll" fromto="-0.01 -0.14 .0025 -0.01 -0.35 .005" mass="3.8"/> -->
                <geom mesh="r_tibia" name="r_tibia" type="mesh"/>
                <geom mesh="r_fibula" name="r_fibula" type="mesh"/>
                <geom name="GasLat_at_shank_r_wrap" pos="-0.0074 -0.074 -0.0033" quat="-0.0298211 0.737282 0.655511 -0.160722" class="wrap" size="0.055 0.05"/>
                <geom name="GasMed_at_shank_r_wrap" pos="-0.0074 -0.074 -0.0033" quat="0.073733 0.735403 0.67187 -0.048347" class="wrap" size="0.055 0.05"/>
                <geom name="GR_at_condyles_r_wrap" pos="-0.003 -0.02 0" quat="0.980067 0 -0.198669 0" class="wrap" size="0.036 0.05"/>
                <geom name="SM_at_condyles_r_wrap" pos="-0.001 -0.02 0" quat="0.99875 0 -0.0499792 0" class="wrap" size="0.0352 0.05"/>
                <geom name="ST_at_condyles_r_wrap" pos="-0.002 -0.0205 0" quat="0.995004 0 -0.0998334 0" class="wrap" size="0.0425 0.05"/>
                <geom name="BF_at_gastroc_r_wrap" pos="-0.058 -0.06 0" class="wrap" size="0.03 0.075"/>
                <site name="bflh_r-P2" pos="-0.0337 -0.035 0.0253"/>
                <site name="bflh_r-P3" pos="-0.0287 -0.0455 0.0303"/>
                <site name="bfsh_r-P2" pos="-0.0301 -0.0419 0.0318"/>
                <site name="edl_r-P1" pos="-0.016 -0.1157 0.0205"/>
                <site name="edl_r-P2" pos="0.0164 -0.376 0.0112"/>
                <site name="ehl_r-P1" pos="-0.014 -0.155 0.0189"/>
                <site name="ehl_r-P2" pos="0.0071 -0.2909 0.0164"/>
                <site name="ehl_r-P3" pos="0.02 -0.3693 -0.0028"/>
                <site name="fdl_r-P1" pos="-0.0023 -0.1832 -0.0018"/>
                <site name="fdl_r-P2" pos="-0.0176 -0.3645 -0.0124"/>
                <site name="fhl_r-P1" pos="-0.031 -0.2163 0.02"/>
                <site name="fhl_r-P2" pos="-0.0242 -0.3671 -0.0076"/>
                <site name="grac_r-P2" pos="-0.0184 -0.0476 -0.0296"/>
                <site name="grac_r-P3" pos="0.0018 -0.0696 -0.0157"/>
                <site name="perbrev_r-P1" pos="-0.0243 -0.2532 0.0251"/>
                <site name="perbrev_r-P2" pos="-0.0339 -0.3893 0.0249"/>
                <site name="perbrev_r-P3" pos="-0.0285 -0.4004 0.0255"/>
                <site name="perlong_r-P1" pos="-0.02 -0.1373 0.0282"/>
                <site name="perlong_r-P2" pos="-0.0317 -0.39 0.0237"/>
                <site name="perlong_r-P3" pos="-0.0272 -0.4014 0.024"/>
                <site name="recfem_r-P5" pos="0.0326 -0.0631 -0.0005"/>
                <site name="sart_r-P3" pos="-0.0251 -0.0401 -0.0365"/>
                <site name="sart_r-P4" pos="-0.0159 -0.0599 -0.0264"/>
                <site name="sart_r-P5" pos="0.0136 -0.081 -0.0026"/>
                <site name="semimem_r-P2" pos="-0.029 -0.0417 -0.0196"/>
                <site name="semiten_r-P2" pos="-0.0312 -0.0508 -0.0229"/>
                <site name="semiten_r-P3" pos="0.0019 -0.0773 -0.0117"/>
                <site name="soleus_r-P1" pos="-0.0076 -0.0916 0.0098"/>
                <site name="tfl_r-P4" pos="0.0108 -0.041 0.0346"/>
                <site name="tibant_r-P1" pos="0.0154 -0.1312 0.0162"/>
                <site name="tibant_r-P2" pos="0.0251 -0.1906 0.0128"/>
                <site name="tibant_r-P3" pos="0.0233 -0.3659 -0.0132"/>
                <site name="tibpost_r-P1" pos="-0.0041 -0.1304 0.0103"/>
                <site name="tibpost_r-P2" pos="-0.0164 -0.3655 -0.0175"/>
                <site name="vasint_r-P5" pos="0.0326 -0.0632 0.0004"/>
                <site name="vaslat_r-P5" pos="0.0325 -0.0634 0.0051"/>
                <site name="vasmed_r-P5" pos="0.0319 -0.0636 -0.0068"/>
                <site name="RKJC" pos="0.0017 -0.0024 -0.0085"/>
                <site name="RTB1" pos="-0.0017 -0.1565 0.0492"/>
                <site name="RTB2" pos="0.037 -0.2301 -0.0039"/>
                <site name="RTB3" pos="0.0114 -0.2952 0.0554"/>
                <site name="RLMAL" pos="-0.005 -0.3888 0.053"/>
                <site name="RMMAL" pos="0.006 -0.3888 -0.038"/>
                <site name="R_tibial_plateau" pos="-0.0081 -0.017 -0.0015"/>
                <site name="GasLat_at_shank_r_site_gaslat_r_side" pos="-0.0512647 -0.0235815 -0.0514609"/>
                <site name="GasMed_at_shank_r_site_gasmed_r_side" pos="-0.0226964 -0.1301 0.0498879"/>
                <site name="GR_at_condyles_r_site_grac_r_side" pos="-0.0513804 -0.042587 0.0198669"/>
                <site name="SM_at_condyles_r_site_semimem_r_side" pos="-0.0387876 -0.035171 -0.0182577"/>
                <site name="ST_at_condyles_r_site_semiten_r_side" pos="-0.0428471 -0.0468901 -0.0181631"/>
                <site name="BF_at_gastroc_r_site_bfsh_r_side" pos="-0.0687049 -0.0256284 0.0426731"/>
                <body name="talus_r" pos="-0.01 -0.4 0">
                    <site name ="ankle_r_location" pos ="0 0 0"/>
                    <site name="ankle_r" class="myo_leg_marker"/>
                    <joint axis="-0.105014 -0.174022 0.979126" name="ankle_angle_r" pos="0 0 0" range="-0.698132 0.523599"/>
                    <geom mesh="r_talus" name="r_talus" type="mesh"/>
                    <site name="RAJC" pos="0 0 0"/>
                    <body name="calcn_r" pos="-0.04877 -0.04195 0.00792">
                        <inertial pos="0.0821377 0.0108024 -0.000944392" quat="0.502987 0.541341 0.493601 0.458598" mass="1.14" diaginertia="0.00313636 0.00297113 0.000941737" />
                        <joint axis="0.78718 0.604747 -0.120949" name="subtalar_angle_r" pos="0 0 0" range="-0.349066 0.349066"/>
                        <geom mesh="r_foot" name="r_foot" type="mesh"/>
                        <site name="edl_r-P3" pos="0.0919 0.036 0.0008"/>
                        <site name="edl_r-P4" pos="0.1616 0.0055 0.013"/>
                        <site name="ehl_r-P4" pos="0.097 0.0389 -0.0211"/>
                        <site name="ehl_r-P5" pos="0.1293 0.0309 -0.0257"/>
                        <site name="ehl_r-P6" pos="0.1734 0.0139 -0.028"/>
                        <site name="fdl_r-P3" pos="0.0436 0.0315 -0.028"/>
                        <site name="fdl_r-P4" pos="0.0708 0.0176 -0.0263"/>
                        <site name="fdl_r-P5" pos="0.1658 -0.0081 0.0116"/>
                        <site name="fhl_r-P3" pos="0.0374 0.0276 -0.0241"/>
                        <site name="fhl_r-P4" pos="0.1038 0.0068 -0.0256"/>
                        <site name="fhl_r-P5" pos="0.1726 -0.0053 -0.0269"/>
                        <site name="gaslat_r-P2" pos="0.0044 0.031 -0.0053"/>
                        <site name="gasmed_r-P2" pos="0.0044 0.031 -0.0053"/>
                        <site name="perbrev_r-P4" pos="0.0471 0.027 0.0233"/>
                        <site name="perbrev_r-P5" pos="0.0677 0.0219 0.0343"/>
                        <site name="perlong_r-P4" pos="0.0438 0.023 0.0221"/>
                        <site name="perlong_r-P5" pos="0.0681 0.0106 0.0284"/>
                        <site name="perlong_r-P6" pos="0.0852 0.0069 0.0118"/>
                        <site name="perlong_r-P7" pos="0.1203 0.0085 -0.0184"/>
                        <site name="soleus_r-P2" pos="0.0044 0.031 -0.0053"/>
                        <site name="tibant_r-P4" pos="0.1166 0.0178 -0.0305"/>
                        <site name="tibpost_r-P3" pos="0.0417 0.0334 -0.0286"/>
                        <site name="tibpost_r-P4" pos="0.0772 0.0159 -0.0281"/>
                        <site name="RCAL" pos="-0.025 0.02 -0.005"/>
                        <site name="RTOE" pos="0.205 0.0297 -0.03"/>
                        <site name="RMT5" pos="0.145 0.0249 0.059"/>
                        <!-- <geom name="r_foot_col1" size=".02" class="coll" fromto="0.175 0 -.03 0.010 0 -.01"/> -->
                        <!-- <geom name="l_foot_col2" size=".02" class="coll" fromto="0.155 0 0.00 0.010 0 0.00"/> -->
                        <!-- <geom name="r_foot_col3" size=".02" class="coll" fromto="0.140 0 0.03 0.010 0 0.01"/> -->
                        <!-- <geom name="r_foot_col4" type="ellipsoid" size=".085 .035 0.04" class="coll" pos="0.08 .02 0" euler="0 0 -.2"/> -->
                        <site name="r_foot_touch" type="box" pos="0.09 -.01 0.0" size=".1 .01 .055" euler="0 0 0" class="myo_leg_touch"/>

                        <body name="toes_r" pos="0.1788 -0.002 0.00108">
                            <site name= "toe_r_location" pos ="0 0 0"/>
                            <site name="toe_r" class="myo_leg_marker"/>
                            <joint axis="0.580954 0 -0.813936" name="mtp_angle_r" pos="0 0 0" range="-0.523599 0.523599"/>
                            <!-- <geom name="r_bofoot_col1" size=".0175 .045" class="coll" zaxis="0.880954 0 -0.813936" pos="0.04 0 .01"/> -->
                            <!-- <geom name="r_bofoot_col2" size=".02 .040" class="coll" zaxis="0.580954 0 -0.813936" pos="0.01 0 0"/> -->
                            <geom mesh="r_bofoot" name="r_bofoot" type="mesh"/>
                            <site name="r_toes_touch" type="box" pos="0.0275 -.01 0" size=".04 .01 .0675" euler="0 -.7 0" class="myo_leg_touch"/>
                            <site name="edl_r-P5" pos="0.0003 0.0047 0.0153"/>
                            <site name="edl_r-P6" pos="0.0443 -0.0004 0.025"/>
                            <site name="ehl_r-P7" pos="0.0298 0.0041 -0.0245"/>
                            <site name="ehl_r-P8" pos="0.0563 0.0034 -0.0186"/>
                            <site name="fdl_r-P6" pos="-0.0019 -0.0078 0.0147"/>
                            <site name="fdl_r-P7" pos="0.0285 -0.0071 0.0215"/>
                            <site name="fdl_r-P8" pos="0.0441 -0.006 0.0242"/>
                            <site name="fhl_r-P6" pos="0.0155 -0.0064 -0.0265"/>
                            <site name="fhl_r-P7" pos="0.0562 -0.0102 -0.0181"/>
                        </body>
                    </body>
                </body>
            </body>
            <body name="patella_r" pos="-0.00809 -0.40796 0">
                <joint axis="0 1 0" name="knee_angle_r_beta_translation2" pos="0 0 0" range="-0.0408267 -0.0108281" type="slide"/>
                <joint axis="1 0 0" name="knee_angle_r_beta_translation1" pos="0 0 0" range="-0.0227731 0.0524192" type="slide"/>
                <joint axis="0 0 1" name="knee_angle_r_beta_rotation1" pos="0 0 0" range="-1.79241 0.010506"/>
                <geom mesh="r_patella" name="r_patella" type="mesh"/>
                <site name="recfem_r-P2" pos="0.01 0.049 0.0007"/>
                <site name="recfem_r-P3" pos="0.0121 0.0437 -0.001"/>
                <site name="recfem_r-P4" pos="0.005 0.0025 0"/>
                <site name="vasint_r-P3" pos="0.0058 0.048 -0.0006"/>
                <site name="vasint_r-P4" pos="0.005 0.0025 -0.0004"/>
                <site name="vaslat_r-P3" pos="0.0103 0.0423 0.0141"/>
                <site name="vaslat_r-P4" pos="0.005 0.0025 0.0073"/>
                <site name="vasmed_r-P3" pos="0.0063 0.0445 -0.017"/>
                <site name="vasmed_r-P4" pos="0.005 0.0025 -0.0085"/>
            </body>
        </body>
        <body name="femur_l" pos="-0.056276 -0.07849 -0.07726">
            <site name ="hip_l_location" pos ="0 0 0"/>
            <site name="hip_l" class="myo_leg_marker"/>
            <inertial pos="0 -0.195 0.0005" quat="0.7062 -0.708013 0 0" mass="8.4" diaginertia="0.1694 0.1694 0.0245269" />
            <joint axis="0 0 1" name="hip_flexion_l" pos="0 0 0" range="-0.523599 2.0944"/>
            <joint axis="-1 0 0" name="hip_adduction_l" pos="0 0 0" range="-0.872665 0.523599"/>
            <joint axis="0 -1 0" name="hip_rotation_l" pos="0 0 0" range="-0.698132 0.698132"/>
            <!-- <geom name="l_femur1_col" size=".080" class="coll" fromto="0 0 -.02 0 -0.2 -.015" mass="4"/> -->
            <!-- <geom name="l_femur2_col" size=".067" class="coll" fromto="0 -0.2 -.015 0 -0.39 -.005" mass="2"/> -->
            <geom mesh="l_femur" name="l_femur" type="mesh"/>
            <geom name="Gastroc_at_condyles_l_wrap" pos="0.005 -0.41 0" class="wrap" size="0.025 0.05"/>
            <geom name="KnExt_at_fem_l_wrap" pos="0.00358828 -0.402732 -0.00209111" quat="0.999192 0.0311532 -0.025365 -0.00079084" class="wrap" size="0.025 0.05"/>
            <geom name="AB_at_femshaft_l_wrap" pos="0.0146434 -0.112595 -0.023365" quat="0.671362 -0.735248 -0.0628354 0.0688147" class="wrap" size="0.0165 0.035"/>
            <geom name="AL_at_femshaft_l_wrap" pos="0.0307327 -0.231909 -0.0151137" quat="0.629067 -0.774355 -0.0429971 0.0529276" class="wrap" size="0.0201 0.05"/>
            <geom name="AMprox_at_femshaft_l_wrap" pos="0.00518299 -0.0728948 -0.025403" quat="0.689646 -0.718132 -0.0645174 0.0671823" class="wrap" size="0.0211 0.035"/>
            <geom name="AMmid_at_femshaft_l_wrap" pos="0.0230125 -0.160711 -0.0205842" quat="0.690996 -0.719631 -0.0472547 0.0492129" class="wrap" size="0.0214 0.06"/>
            <geom name="AMdist_at_femshaft_l_wrap" pos="0.0316065 -0.260736 -0.0093646" quat="0.652657 -0.751902 -0.061082 0.0703703" class="wrap" size="0.0218 0.1"/>
            <geom name="AMisch_at_condyles_l_wrap" pos="-0.0226511 -0.376831 0.00315437" quat="0.638263 -0.734777 0.150578 -0.173347" class="wrap" size="0.04 0.12"/>
            <geom name="PECT_at_femshaft_l_wrap" pos="0.00608573 -0.0845029 -0.0304405" quat="0.610649 -0.779832 -0.0849157 0.108442" class="wrap" size="0.015 0.025"/>
            <site name="addbrev_l-P2" pos="-0.002 -0.118 -0.0249"/>
            <site name="addlong_l-P2" pos="0.0113 -0.2394 -0.0158"/>
            <site name="addmagDist_l-P2" pos="0.0112 -0.2625 -0.0193"/>
            <site name="addmagIsch_l-P2" pos="0.0048 -0.388 0.0327"/>
            <site name="addmagMid_l-P2" pos="0.0024 -0.1624 -0.0292"/>
            <site name="addmagProx_l-P2" pos="-0.0153 -0.0789 -0.032"/>
            <site name="bfsh_l-P1" pos="0.005 -0.2111 -0.0234"/>
            <site name="gaslat_l-P1" pos="-0.003 -0.3814 -0.0277"/>
            <site name="gasmed_l-P1" pos="0.008 -0.3788 0.0208"/>
            <site name="glmax1_l-P3" pos="-0.0444 -0.0326 -0.0302"/>
            <site name="glmax1_l-P4" pos="-0.0277 -0.0566 -0.047"/>
            <site name="glmax2_l-P3" pos="-0.045 -0.0584 -0.0252"/>
            <site name="glmax2_l-P4" pos="-0.0156 -0.1016 -0.0419"/>
            <site name="glmax3_l-P3" pos="-0.0281 -0.1125 -0.0094"/>
            <site name="glmax3_l-P4" pos="-0.006 -0.1419 -0.0411"/>
            <site name="glmed1_l-P2" pos="-0.0218 -0.0117 -0.0555"/>
            <site name="glmed2_l-P2" pos="-0.0258 -0.0058 -0.0527"/>
            <site name="glmed3_l-P2" pos="-0.0309 -0.0047 -0.0518"/>
            <site name="glmin1_l-P2" pos="-0.0072 -0.0104 -0.056"/>
            <site name="glmin2_l-P2" pos="-0.0096 -0.0104 -0.056"/>
            <site name="glmin3_l-P2" pos="-0.0135 -0.0083 -0.055"/>
            <site name="iliacus_l-P3" pos="-0.0023 -0.0565 -0.0139"/>
            <site name="iliacus_l-P4" pos="-0.0122 -0.0637 -0.0196"/>
            <site name="piri_l-P3" pos="-0.0148 -0.0036 -0.0437"/>
            <site name="psoas_l-P3" pos="-0.0132 -0.0467 -0.0046"/>
            <site name="psoas_l-P4" pos="-0.0235 -0.0524 -0.0088"/>
            <site name="sart_l-P2" pos="-0.003 -0.3568 0.0421"/>
            <site name="tfl_l-P2" pos="0.0294 -0.0995 -0.0597"/>
            <site name="tfl_l-P3" pos="0.0107 -0.405 -0.0324"/>
            <site name="vasint_l-P1" pos="0.029 -0.1924 -0.031"/>
            <site name="vasint_l-P2" pos="0.0335 -0.2084 -0.0285"/>
            <site name="vaslat_l-P1" pos="0.0048 -0.1854 -0.0349"/>
            <site name="vaslat_l-P2" pos="0.0269 -0.2591 -0.0409"/>
            <site name="vasmed_l-P1" pos="0.014 -0.2099 -0.0188"/>
            <site name="vasmed_l-P2" pos="0.0356 -0.2769 -0.0009"/>
            <site name="LHJC" pos="0 0 0"/>
            <site name="LTH1" pos="0.018 -0.15 -0.064"/>
            <site name="LTH2" pos="0.08 -0.23 -0.0047"/>
            <site name="LTH3" pos="0.01 -0.3 -0.06"/>
            <site name="LLFC" pos="0 -0.404 -0.05"/>
            <site name="LMFC" pos="0 -0.404 0.05"/>
            <site name="KnExt_at_fem_l_site_recfem_l_side" pos="0.028412 -0.418795 0.0326861"/>
            <site name="KnExt_at_fem_l_site_vasint_l_side" pos="0.0140493 -0.375075 0.00469312"/>
            <site name="KnExt_at_fem_l_site_vaslat_l_side" pos="0.0164816 -0.378983 0.0366504"/>
            <site name="KnExt_at_fem_l_site_vasmed_l_side" pos="0.0179815 -0.374402 -0.023524"/>
            <site name="AB_at_femshaft_l_site_addbrev_l_side" pos="-0.00249969 -0.126567 -0.0261656"/>
            <site name="AL_at_femshaft_l_site_addlong_l_side" pos="0.0113183 -0.263228 -0.00405212"/>
            <site name="AMprox_at_femshaft_l_site_addmagProx_l_side" pos="-0.0232677 -0.056978 -0.0222299"/>
            <site name="AMmid_at_femshaft_l_site_addmagMid_l_side" pos="-0.0100694 -0.108641 -0.0230602"/>
            <site name="AMdist_at_femshaft_l_site_addmagDist_l_side" pos="0.0146959 -0.298529 -0.0158276"/>
            <site name="AMisch_at_condyles_l_site_addmagIsch_l_side" pos="-0.0360341 -0.49032 0.0446456"/>
            <body name="tibia_l" pos="-4.6e-07 -0.404425 0.00126526">
                <site name ="knee_l_location" pos="0 0 0"/>
                <site name="knee_l" class="myo_leg_marker"/>
                <inertial pos="-0.005 -0.175 -0.0025" quat="0.712137 -0.701754 0.0200501 0" mass="3.8" diaginertia="0.0771589 0.0771589 0.00690387" />
                <joint axis="-0.992246 -0.123982 -0.00878916" name="knee_angle_l_translation2" pos="0 0 0" range="-0.006792 -7.69254e-11" type="slide"/>
                <joint axis="-0.124293 0.989762 0.0701648" name="knee_angle_l_translation1" pos="0 0 0" range="9.53733e-08 0.00159883" type="slide"/>
                <joint axis="3.98373e-10 0.0707131 -0.997497" name="knee_angle_l" pos="0 0 0" range="0 2.0944"/>
                <joint axis="-0.992246 -0.123982 -0.00878916" name="knee_angle_l_rotation2" pos="0 0 0" range="-0.00167821 0.0335354"/>
                <joint axis="-0.124293 0.989762 0.0701648" name="knee_angle_l_rotation3" pos="0 0 0" range="-0.262788 -1.08939e-08"/>
                <!-- <geom name="l_tibia1_col" size=".056" class="coll" fromto="0 0 0 -0.01 -0.14 -.0025" mass="3.8"/> 14cms -->
                <!-- <geom name="l_tibia2_col" size=".048" class="coll" fromto="-0.01 -0.14 -.0025 -0.01 -0.35 -.005" mass="3.8"/> -->
                <geom mesh="l_tibia" name="l_tibia" type="mesh"/>
                <geom mesh="l_fibula" name="l_fibula" type="mesh"/>
                <geom name="GasLat_at_shank_l_wrap" pos="-0.0074 -0.074 0.0033" quat="-0.0298211 -0.737282 -0.655511 -0.160722" class="wrap" size="0.055 0.05"/>
                <geom name="GasMed_at_shank_l_wrap" pos="-0.0074 -0.074 0.0033" quat="0.073733 -0.735403 -0.67187 -0.048347" class="wrap" size="0.055 0.05"/>
                <geom name="GR_at_condyles_l_wrap" pos="-0.003 -0.02 0" quat="0.980067 0 0.198669 0" class="wrap" size="0.036 0.05"/>
                <geom name="SM_at_condyles_l_wrap" pos="-0.001 -0.02 0" quat="0.99875 0 0.0499792 0" class="wrap" size="0.0352 0.05"/>
                <geom name="ST_at_condyles_l_wrap" pos="-0.002 -0.0205 0" quat="0.995004 0 0.0998334 0" class="wrap" size="0.0425 0.05"/>
                <geom name="BF_at_gastroc_l_wrap" pos="-0.058 -0.06 0" class="wrap" size="0.03 0.075"/>
                <site name="bflh_l-P2" pos="-0.0337 -0.035 -0.0253"/>
                <site name="bflh_l-P3" pos="-0.0287 -0.0455 -0.0303"/>
                <site name="bfsh_l-P2" pos="-0.0301 -0.0419 -0.0318"/>
                <site name="edl_l-P1" pos="-0.016 -0.1157 -0.0205"/>
                <site name="edl_l-P2" pos="0.0164 -0.376 -0.0112"/>
                <site name="ehl_l-P1" pos="-0.014 -0.155 -0.0189"/>
                <site name="ehl_l-P2" pos="0.0071 -0.2909 -0.0164"/>
                <site name="ehl_l-P3" pos="0.02 -0.3693 0.0028"/>
                <site name="fdl_l-P1" pos="-0.0023 -0.1832 0.0018"/>
                <site name="fdl_l-P2" pos="-0.0176 -0.3645 0.0124"/>
                <site name="fhl_l-P1" pos="-0.031 -0.2163 -0.02"/>
                <site name="fhl_l-P2" pos="-0.0242 -0.3671 0.0076"/>
                <site name="grac_l-P2" pos="-0.0184 -0.0476 0.0296"/>
                <site name="grac_l-P3" pos="0.0018 -0.0696 0.0157"/>
                <site name="perbrev_l-P1" pos="-0.0243 -0.2532 -0.0251"/>
                <site name="perbrev_l-P2" pos="-0.0339 -0.3893 -0.0249"/>
                <site name="perbrev_l-P3" pos="-0.0285 -0.4004 -0.0255"/>
                <site name="perlong_l-P1" pos="-0.02 -0.1373 -0.0282"/>
                <site name="perlong_l-P2" pos="-0.0317 -0.39 -0.0237"/>
                <site name="perlong_l-P3" pos="-0.0272 -0.4014 -0.024"/>
                <site name="recfem_l-P5" pos="0.0326 -0.0631 0.0005"/>
                <site name="sart_l-P3" pos="-0.0251 -0.0401 0.0365"/>
                <site name="sart_l-P4" pos="-0.0159 -0.0599 0.0264"/>
                <site name="sart_l-P5" pos="0.0136 -0.081 0.0026"/>
                <site name="semimem_l-P2" pos="-0.029 -0.0417 0.0196"/>
                <site name="semiten_l-P2" pos="-0.0312 -0.0508 0.0229"/>
                <site name="semiten_l-P3" pos="0.0019 -0.0773 0.0117"/>
                <site name="soleus_l-P1" pos="-0.0076 -0.0916 -0.0098"/>
                <site name="tfl_l-P4" pos="0.0108 -0.041 -0.0346"/>
                <site name="tibant_l-P1" pos="0.0154 -0.1312 -0.0162"/>
                <site name="tibant_l-P2" pos="0.0251 -0.1906 -0.0128"/>
                <site name="tibant_l-P3" pos="0.0233 -0.3659 0.0132"/>
                <site name="tibpost_l-P1" pos="-0.0041 -0.1304 -0.0103"/>
                <site name="tibpost_l-P2" pos="-0.0164 -0.3655 0.0175"/>
                <site name="vasint_l-P5" pos="0.0326 -0.0632 -0.0004"/>
                <site name="vaslat_l-P5" pos="0.0325 -0.0634 -0.0051"/>
                <site name="vasmed_l-P5" pos="0.0319 -0.0636 0.0068"/>
                <site name="LKJC" pos="0.0017 -0.0024 0.0085"/>
                <site name="LTB1" pos="-0.0017 -0.1565 -0.0492"/>
                <site name="LTB2" pos="0.037 -0.2301 0.0039"/>
                <site name="LTB3" pos="0.0114 -0.2952 -0.0554"/>
                <site name="LLMAL" pos="-0.005 -0.3888 -0.053"/>
                <site name="LMMAL" pos="0.006 -0.3888 0.038"/>
                <site name="L_tibial_plateau" pos="-0.0081 -0.017 0.0015"/>
                <site name="GasLat_at_shank_l_site_gaslat_l_side" pos="-0.0512647 -0.0235815 0.0514609"/>
                <site name="GasMed_at_shank_l_site_gasmed_l_side" pos="-0.0226964 -0.1301 -0.0498879"/>
                <site name="GR_at_condyles_l_site_grac_l_side" pos="-0.0513804 -0.042587 -0.0198669"/>
                <site name="SM_at_condyles_l_site_semimem_l_side" pos="-0.0387876 -0.035171 0.0182577"/>
                <site name="ST_at_condyles_l_site_semiten_l_side" pos="-0.0428471 -0.0468901 0.0181631"/>
                <site name="BF_at_gastroc_l_site_bfsh_l_side" pos="-0.0687049 -0.0256284 -0.0426731"/>
                <body name="talus_l" pos="-0.01 -0.4 0">
                    <site name ="ankle_l_location" pos="0 0 0"/>
                    <site name="ankle_l" class="myo_leg_marker"/>
                    <joint axis="0.105014 0.174022 0.979126" name="ankle_angle_l" pos="0 0 0" range="-0.698132 0.523599"/>
                    <geom mesh="l_talus" name="l_talus" type="mesh"/>
                    <site name="LAJC" pos="0 0 0"/>
                    <body name="calcn_l" pos="-0.04877 -0.04195 -0.00792">
                        <inertial pos="0.0821377 0.0108024 0.000944392" quat="0.541341 0.502987 0.458598 0.493601" mass="1.14" diaginertia="0.00313636 0.00297113 0.000941737" />
                        <joint axis="-0.78718 -0.604747 -0.120949" name="subtalar_angle_l" pos="0 0 0" range="-0.349066 0.349066"/>
                        <geom mesh="l_foot" name="l_foot" type="mesh"/>
                        <site name="edl_l-P3" pos="0.0919 0.036 -0.0008"/>
                        <site name="edl_l-P4" pos="0.1616 0.0055 -0.013"/>
                        <site name="ehl_l-P4" pos="0.097 0.0389 0.0211"/>
                        <site name="ehl_l-P5" pos="0.1293 0.0309 0.0257"/>
                        <site name="ehl_l-P6" pos="0.1734 0.0139 0.028"/>
                        <site name="fdl_l-P3" pos="0.0436 0.0315 0.028"/>
                        <site name="fdl_l-P4" pos="0.0708 0.0176 0.0263"/>
                        <site name="fdl_l-P5" pos="0.1658 -0.0081 -0.0116"/>
                        <site name="fhl_l-P3" pos="0.0374 0.0276 0.0241"/>
                        <site name="fhl_l-P4" pos="0.1038 0.0068 0.0256"/>
                        <site name="fhl_l-P5" pos="0.1726 -0.0053 0.0269"/>
                        <site name="gaslat_l-P2" pos="0.0044 0.031 0.0053"/>
                        <site name="gasmed_l-P2" pos="0.0044 0.031 0.0053"/>
                        <site name="perbrev_l-P4" pos="0.0471 0.027 -0.0233"/>
                        <site name="perbrev_l-P5" pos="0.0677 0.0219 -0.0343"/>
                        <site name="perlong_l-P4" pos="0.0438 0.023 -0.0221"/>
                        <site name="perlong_l-P5" pos="0.0681 0.0106 -0.0284"/>
                        <site name="perlong_l-P6" pos="0.0852 0.0069 -0.0118"/>
                        <site name="perlong_l-P7" pos="0.1203 0.0085 0.0184"/>
                        <site name="soleus_l-P2" pos="0.0044 0.031 0.0053"/>
                        <site name="tibant_l-P4" pos="0.1166 0.0178 0.0305"/>
                        <site name="tibpost_l-P3" pos="0.0417 0.0334 0.0286"/>
                        <site name="tibpost_l-P4" pos="0.0772 0.0159 0.0281"/>
                        <site name="LCAL" pos="-0.025 0.02 0.005"/>
                        <site name="LTOE" pos="0.205 0.0297 0.03"/>
                        <site name="LMT5" pos="0.145 0.0249 -0.059"/>
                        <!-- <geom name="l_foot_col1" size=".02" class="coll" fromto="0.175 0 0.03 0.010 0 0.01"/> -->
                        <!-- <geom name="l_foot_col2" size=".02" class="coll" fromto="0.155 0 0.00 0.010 0 0.00"/> -->
                        <!-- <geom name="l_foot_col3" size=".02" class="coll" fromto="0.140 0 -.03 0.010 0 -.01"/> -->
                        <!-- <geom name="l_foot_col4" type="ellipsoid" size=".085 .035 0.04" class="coll" pos="0.08 .02 0" euler="0 0 -.2"/> -->
                        <site name="l_foot_touch" type="box" pos="0.09 -.01 0.0" size=".1 .01 .055" euler="0 0 0" class="myo_leg_touch"/>

                        <body name="toes_l" pos="0.1788 -0.002 -0.00108">
                            <site name ="toe_l_location" pos="0 0 0"/>
                            <site name="toe_l" class="myo_leg_marker"/>
                            <joint axis="-0.580954 0 -0.813936" name="mtp_angle_l" pos="0 0 0" range="-0.523599 0.523599"/>
                            <!-- <geom name="l_bofoot_col1" size=".0175 .045" class="coll" zaxis="-0.880954 0 -0.813936" pos="0.04 0 -.01"/> -->
                            <!-- <geom name="l_bofoot_col2" size=".02 .040" class="coll" zaxis="-0.580954 0 -0.813936" pos="0.01 0 0"/> -->
                            <geom mesh="l_bofoot" name="l_bofoot" type="mesh"/>
                            <site name="l_toes_touch" type="box" pos="0.0275 -.01 -.000" size=".04 .01 .0675" euler="0 .7 0" class="myo_leg_touch"/>
                            <site name="edl_l-P5" pos="0.0003 0.0047 -0.0153"/>
                            <site name="edl_l-P6" pos="0.0443 -0.0004 -0.025"/>
                            <site name="ehl_l-P7" pos="0.0298 0.0041 0.0245"/>
                            <site name="ehl_l-P8" pos="0.0563 0.0034 0.0186"/>
                            <site name="fdl_l-P6" pos="-0.0019 -0.0078 -0.0147"/>
                            <site name="fdl_l-P7" pos="0.0285 -0.0071 -0.0215"/>
                            <site name="fdl_l-P8" pos="0.0441 -0.006 -0.0242"/>
                            <site name="fhl_l-P6" pos="0.0155 -0.0064 0.0265"/>
                            <site name="fhl_l-P7" pos="0.0562 -0.0102 0.0181"/>
                        </body>
                    </body>
                </body>
            </body>
            <body name="patella_l" pos="-0.00809 -0.40796 0">
                <joint axis="0 1 0" name="knee_angle_l_beta_translation2" pos="0 0 0" range="-0.0408267 -0.0108281" type="slide"/>
                <joint axis="1 0 0" name="knee_angle_l_beta_translation1" pos="0 0 0" range="-0.0227731 0.0524192" type="slide"/>
                <joint axis="0 0 1" name="knee_angle_l_beta_rotation1" pos="0 0 0" range="-1.79241 0.010506"/>
                <geom mesh="l_patella" name="l_patella" type="mesh"/>
                <site name="recfem_l-P2" pos="0.01 0.049 -0.0007"/>
                <site name="recfem_l-P3" pos="0.0121 0.0437 0.001"/>
                <site name="recfem_l-P4" pos="0.005 0.0025 0"/>
                <site name="vasint_l-P3" pos="0.0058 0.048 0.0006"/>
                <site name="vasint_l-P4" pos="0.005 0.0025 0.0004"/>
                <site name="vaslat_l-P3" pos="0.0103 0.0423 -0.0141"/>
                <site name="vaslat_l-P4" pos="0.005 0.0025 -0.0073"/>
                <site name="vasmed_l-P3" pos="0.0063 0.0445 0.017"/>
                <site name="vasmed_l-P4" pos="0.005 0.0025 0.0085"/>
            </body>
        </body>
      </body>

      <geom conaffinity="3" condim="3" friction="1 .1 .1" material="plane" name="terrain_mesh"
            rgba=".9 .9 .9 1"
            size="10 5 0.1"
            type="plane"/>
   
      <body name="torso" pos="0 0 1">
         <site name ="pelvissite" pos ="0 0 0"/>
         <inertial diaginertia="8.0012      8.2603     0.55024" mass="51.1774"
                   pos="-0.058503 -3.5387e-05     0.28026"/>
         <geom conaffinity="0" contype="0" density="0" group="1" mesh="PelvisLink" type="mesh" name="pelvismesh"/>
         <!-- <freejoint name="root"/> -->
         <site group="3" name="pelvis_imu" pos="-0.16445   -0.014625     0.19109"
               quat="0.5        -0.5        -0.5         0.5"
               size=".01"/>
         <site group="3" name="thorax_imu" pos="-0.14           0         0.5"
               quat="0.70711           0     0.70711           0"
               size=".01"/>
         <body name="LeftFrontalHipLink" pos="0 0.089 0">
            <inertial diaginertia="0.036612 0.0349177 0.00740632" mass="3.6752"
                      pos="-0.18696 0.095567 0.018365"
                      quat="0.453895 0.291805 -0.721185 0.43442"/>
            <joint axis="1 0 0" name="LeftFrontalHipJoint" pos="0 0 0" range="-0.2 0.3"/>
            <geom conaffinity="0" contype="0" density="0" group="1" mesh="LeftFrontalHipLink"
                  type="mesh"/>
            <body name="LeftTransverseHipLink" pos="-0.135 0.169 0">
               <site name ="LeftTransverseHipSite" pos="0 0 0"/>
               <inertial diaginertia="0.0259937 0.0259386 0.00622165" mass="4.4176"
                         pos="0.069171 -0.008671 0.004224"
                         quat="-0.114265 0.696606 -0.205723 0.677762"/>
               <joint axis="0 0 1" name="LeftTransverseHipJoint" pos="0 0 0" range="-0.2 0.3"/>
               <geom conaffinity="0" contype="0" density="0" group="1" mesh="LeftTransverseHipLink"
                     type="mesh"/>
               <body name="LeftSagittalHipLink" pos="0.135 0 0">
                  <site name ="LeftSagittalHipSite" pos="0 0 0"/>
                  <inertial diaginertia="0.409772 0.397989 0.0563415" mass="14.0668"
                            pos="0.014492 -0.011478 -0.18231"
                            quat="0.544811 -0.0185674 0.0146821 0.838225"/>
                  <joint axis="0 1 0" name="LeftSagittalHipJoint" pos="0 0 0" range="-2 0.3"/>
                  <geom conaffinity="0" contype="0" density="0" group="1" mesh="LeftSagittalHipLink"
                        type="mesh"/>
                  <body name="LeftSagittalKneeLink" pos="0 0.0049114 -0.38">
                     <site name ="LeftSagittalKneeSite" pos ="0 0 0"/>
                     <inertial diaginertia="0.429747 0.388534 0.104179" mass="13.3561"
                               pos="-0.051952 -0.090967 -0.20236"
                               quat="0.942179 -0.149291 0.11288 -0.277974"/>
                     <joint axis="0 1 0" name="LeftSagittalKneeJoint" pos="0 0 0" range="0 1.9"/>
                     <geom conaffinity="0" contype="0" density="0" group="1" mesh="LeftSagittalKneeLink"
                           type="mesh" name="leftkneemesh"/>
                     <site group="3" name="left_tibia_imu" pos="-0.14067   -0.074092    -0.39348"
                           quat="2.3108e-07 -2.3108e-07     0.70711    -0.70711"
                           size=".01"/>
                     <body name="LeftSagittalAnkleLink" pos="0 -0.16942 -0.408"
                           quat="0.997564 0 0 0.0697583">
                        <!-- <site name = "LeftSagittalAnkleSite" pos ="0 0 0"/> -->
                        <inertial diaginertia="0.00498533 0.00498533 0.00498533" mass="1.6764"
                                  pos="-0.043917 0.056353 -0.038953"
                                  quat="0.390876 0.856905 0.0797629 -0.326448"/>
                        <joint axis="0 1 0" name="LeftSagittalAnkleJoint" pos="0 0 0" range="-0.3 0.2"/>
                        <geom conaffinity="0" contype="0" density="0" group="1" mesh="LeftSagittalAnkleLink"
                              type="mesh"/>
                        <body name="LeftHenkeAnkleLink" pos="0 0 0">
                           <site name ="LeftHenkeAnkleSite" pos= "0 0 0"/>
                           <inertial diaginertia="0.0874752 0.0731099 0.0168659" mass="3.9663"
                                     pos="-0.020021 1.6256e-06 -0.095894"
                                     quat="0.350735 0.50826 0.290766 0.73083"/>
                           <joint axis="0.788011 0 0.615661" name="LeftHenkeAnkleJoint" pos="0 0 0"
                                  range="-0.3 0.3"/>
                           <geom conaffinity="0" contype="0" density="0" group="1" mesh="LeftHenkeAnkleLink"
                                 quat="0.945518 0 -0.32557 0"
                                 type="mesh" name="leftfootmesh"/>
                           <geom condim="3" friction="1 0.1 0.001" name="left_sole" pos="0.06 -3.3e-05 -0.15975"
                                 contype="1"
                                 conaffinity="0"
                                 solimp="0.9 0.95 0.001 0.4 2" 
                                 solref="0.02 1"
                                 quat="0.707105 0 -0.707108 0"
                                 rgba="1 0 0 1"
                                 size="0.0049535 0.059645 0.1375"
                                 type="box"/>
                           <!-- <geom condim="3" friction="1" name="left_toe" pos="0.2195 0 -0.1537"
                                 contype="1"
                                 conaffinity="0"
                                 quat="0.6018 0 -0.7986 0"
                                 rgba="1 0 0 1"
                                 size="0.0049535 0.059645 0.022"
                                 type="box"/> -->
                           <!-- <geom condim="3" friction="1" name="left_heel" pos="-0.0940 0 -0.1566"
                                 contype="1"
                                 conaffinity="0"
                                 quat="0.7716 0 -0.6361 0"
                                 rgba="1 0 0 1"
                                 size="0.0049535 0.059645 0.0165"
                                 type="box"/> -->
                           <site name="left_foot_imu" pos="-0.036966       0.015    -0.13705"
                                 quat="-1.6377e-07    -0.94552  -5.639e-08     0.32557"
                                 size=".01"/>
                           <site group="2" name="opto1" pos="0.17825      0.0285     -0.1598" quat="1 0 0 1"
                                 size="0.05"/>
                           <site group="2" name="opto2" pos="0.17825     -0.0285     -0.1598" quat="1 0 0 1"
                                 size="0.05"/>
                           <site group="2" name="opto3" pos="-0.063753     0.02625     -0.1598" quat="1 0 0 1"
                                 size="0.05"/>
                           <site group="2" name="opto4" pos="-0.063753    -0.02625     -0.1598" quat="1 0 0 1"
                                 size="0.05"/>
                        </body>
                     </body>
                  </body>
               </body>
            </body>
         </body>
         <body name="RightFrontalHipLink" pos="0 -0.089 0">
            <inertial diaginertia="0.0365973 0.0349128 0.00740791" mass="3.6752"
                      pos="-0.18696 -0.095567 0.01843"
                      quat="0.292578 0.454629 -0.434128 0.720585"/>
            <joint axis="1 0 0" name="RightFrontalHipJoint" pos="0 0 0" range="-0.3 0.2"/>
            <geom conaffinity="0" contype="0" density="0" group="1" mesh="RightFrontalHipLink"
                  type="mesh"/>
            <body name="RightTransverseHipLink" pos="-0.135 -0.169 0">
               <inertial diaginertia="0.0259901 0.0259386 0.00622121" mass="4.4176"
                         pos="0.069166 0.008663 0.004212"
                         quat="0.111328 0.697511 0.202883 0.678177"/>
               <joint axis="0 0 1" name="RightTransverseHipJoint" pos="0 0 0" range="-0.3 0.2"/>
               <geom conaffinity="0" contype="0" density="0" group="1" mesh="RightTransverseHipLink"
                     type="mesh"/>
               <body name="RightSagittalHipLink" pos="0.135 0 0">
                  <site name ="RightSagittalHipSite" pos ="0 0 0"/>
                  <inertial diaginertia="0.409772 0.397989 0.0563415" mass="14.0668"
                            pos="0.014492 0.011478 -0.18231"
                            quat="0.838225 0.0146821 -0.0185674 0.544811"/>
                  <joint axis="0 1 0" name="RightSagittalHipJoint" pos="0 0 0" range="-2 0.3"/>
                  <geom conaffinity="0" contype="0" density="0" group="1" mesh="RightSagittalHipLink"
                        type="mesh" name ="righthipmesh"/>
                  <body name="RightSagittalKneeLink" pos="0 -0.0049114 -0.38">
                     <site name = "RightSagittalKneeSite" pos="0 0 0"/>
                     <inertial diaginertia="0.429747 0.388534 0.104179" mass="13.3561"
                               pos="-0.051952 0.090967 -0.20236"
                               quat="0.942179 0.149291 0.11288 0.277974"/>
                     <joint axis="0 1 0" name="RightSagittalKneeJoint" pos="0 0 0" range="0 1.9"/>
                     <geom conaffinity="0" contype="0" density="0" group="1" mesh="RightSagittalKneeLink"
                           type="mesh" name ="rightkneemesh"/>
            
                     <site group="3" name="right_tibia_imu" pos="-0.11573    0.074342    -0.39348"
                           quat="0.70711    -0.70711           0           0"
                           size=".01"/>
                     <body name="RightSagittalAnkleLink" pos="0 0.16942 -0.408"
                           quat="0.997564 0 0 -0.0697583">
                        <!-- <site name = "RightSagittalAnkleSite" pos ="0 0 0"/> -->
                        <inertial diaginertia="0.00498533 0.00498533 0.00498533" mass="1.6764"
                                  pos="-0.043917 -0.056352 -0.038953"
                                  quat="0.856905 0.390876 0.326448 -0.0797629"/>
                        <joint axis="0 1 0" name="RightSagittalAnkleJoint" pos="0 0 0" range="-0.3 0.2"/>
                        <geom conaffinity="0" contype="0" density="0" group="1" mesh="RightSagittalAnkleLink"
                              type="mesh"/>
                        <body name="RightHenkeAnkleLink" pos="0 0 0">
                           <site name="RightHenkeAnkleSite" pos ="0 0 0"/>
                           <inertial diaginertia="0.0874752 0.0731099 0.0168659" mass="3.9663"
                                     pos="-0.020021 -1.6256e-06 -0.095894"
                                     quat="0.73083 0.290766 0.50826 0.350735"/>
                           <joint axis="0.788011 0 0.615661" name="RightHenkeAnkleJoint" pos="0 0 0"
                                  range="-0.3 0.3"/>
                           <geom conaffinity="0" contype="0" density="0" group="1" mesh="RightHenkeAnkleLink"
                                 quat="0.945518 0 -0.32557 0"
                                 type="mesh" name="rightfootmesh"/>
                           <geom condim="3" friction="1 0.1 0.001" name="right_sole" pos="0.06 -3.3e-05 -0.15975"
                                 contype="2"  
                                 conaffinity="0" 
                                 solimp="0.9 0.95 0.001 0.4 2" 
                                 solref="0.02 1"
                                 quat="0.707105 0 -0.707108 0"
                                 rgba="1 0 0 1"
                                 size="0.0049535 0.059645 0.1375"
                                 type="box"/>
                           <!-- <geom condim="3" friction="1" name="right_toe" pos="0.2195 0 -0.1537"
                                 contype="2"
                                 conaffinity="0" 
                                 quat="0.6018 0 -0.7986 0"
                                 rgba="1 0 0 1"
                                 size="0.0049535 0.059645 0.022"
                                 type="box"/>
                           <geom condim="3" friction="1" name="right_heel" pos="-0.0940 0 -0.1566"
                                 contype="2"
                                 conaffinity="0" 
                                 quat="0.7716 0 -0.6361 0"
                                 rgba="1 0 0 1"
                                 size="0.0049535 0.059645 0.0165"
                                 type="box"/> -->
                           <site name="right_foot_imu" pos="-0.036966       0.015    -0.13705"
                                 quat="-1.6377e-07    -0.94552  -5.639e-08     0.32557"
                                 size=".01"/>
                           <site group="2" name="opto5" pos="0.17825      0.0285     -0.1598" quat="1 0 0 1"
                                 size="0.05"/>
                           <site group="2" name="opto6" pos="0.17825     -0.0285     -0.1598" quat="1 0 0 1"
                                 size="0.05"/>
                           <site group="2" name="opto7" pos="-0.063753     0.02625     -0.1598" quat="1 0 0 1"
                                 size="0.05"/>
                           <site group="2" name="opto8" pos="-0.063753    -0.02625     -0.1598" quat="1 0 0 1"
                                 size="0.05"/>
                        </body>
                     </body>
                  </body>
               </body>
            </body>
         </body>
      </body>
   </worldbody>

    <contact>
        <!-- <pair condim="3" friction="1 1 0.005 0.0001 0.0001" geom1="r_femur" geom2="righthipmesh" margin="0.0001"
           /> -->
        <pair geom1="ST_at_condyles_r_wrap" geom2="rightkneemesh" margin="0.0001"
           />
        <pair geom1="ST_at_condyles_l_wrap" geom2="rightkneemesh" margin="0.0001"
           />
        <pair geom1="l_foot" geom2="leftfootmesh" margin="0.0001"
           />
        <pair geom1="r_foot" geom2="rightfootmesh" margin="0.0001"
           />
    </contact>

    <tendon>
        <spatial name= "pelvisconnect" springlength= "0.00000001">
            <site site ="pelvislocation"/>
            <site site ="pelvissite"/>
        </spatial>

        <spatial name= "righthipconnect" springlength= "0.00000001">
            <site site ="hip_r_location"/>
            <site site ="RightSagittalHipSite"/>
        </spatial>

        <spatial name= "rightkneeconnect" springlength= "0.00000001">
            <site site ="knee_r_location"/>
            <site site ="RightSagittalKneeSite"/>
        </spatial>

        <spatial name= "rightankleconnect" springlength= "0.000001">
            <site site ="ankle_r_location"/>
            <site site ="RightHenkeAnkleSite"/>
        </spatial>

        <spatial name= "righttoeconnect" springlength= "0.00000001">
            <site site ="toe_r_location"/>
            <site site ="right_foot_imu"/>
        </spatial>

         <spatial name= "lefthipconnect" springlength= "0.0000001">
            <site site ="hip_r_location"/>
            <site site ="LeftSagittalHipSite"/>
        </spatial>

        <spatial name= "leftkneeconnect" springlength= "0.0000001">
            <site site ="knee_l_location"/>
            <site site ="LeftSagittalKneeSite"/>
        </spatial>

        <spatial name= "leftankleconnect" springlength= "0.000001">
            <site site ="ankle_l_location"/>
            <site site ="LeftHenkeAnkleSite"/>
        </spatial>

        <spatial name= "lefttoeconnect" springlength= "0.000001">
            <site site ="toe_l_location"/>
            <site site ="left_foot_imu"/>
        </spatial>

        <spatial name="addbrev_r_tendon" springlength="0.0354503">
            <site site="addbrev_r-P1"/>
            <site site ="pelvissite"/>
            <!-- <geom geom="AB_at_femshaft_r_wrap" sidesite="AB_at_femshaft_r_site_addbrev_r_side"/> -->
            <site site="addbrev_r-P2"/>
        </spatial>
        <spatial name="addlong_r_tendon" springlength="0.131799">
            <site site="addlong_r-P1"/>
            <!-- <site site ="pelvissite"/> -->
            <!-- <geom geom="AL_at_femshaft_r_wrap" sidesite="AL_at_femshaft_r_site_addlong_r_side"/> -->
            <site site="addlong_r-P2"/>
        </spatial>
        <spatial name="addmagDist_r_tendon" springlength="0.0873807">
            <site site="addmagDist_r-P1"/>
            <!-- <site site ="pelvissite"/> -->
            <!-- <geom geom="AMdist_at_femshaft_r_wrap" sidesite="AMdist_at_femshaft_r_site_addmagDist_r_side"/> -->
            <site site="addmagDist_r-P2"/>
        </spatial>
        <spatial name="addmagIsch_r_tendon" springlength="0.216343">
            <site site="addmagIsch_r-P1"/>
            <!-- <site site ="pelvissite"/> -->
            <!-- <geom geom="AMisch_at_condyles_r_wrap" sidesite="AMisch_at_condyles_r_site_addmagIsch_r_side"/> -->
            <site site="addmagIsch_r-P2"/>
        </spatial>
        <spatial name="addmagMid_r_tendon" springlength="0.0466277">
            <site site="addmagMid_r-P1"/>
            <!-- <site site ="pelvissite"/> -->
            <!-- <geom geom="AMmid_at_femshaft_r_wrap" sidesite="AMmid_at_femshaft_r_site_addmagMid_r_side"/> -->
            <site site="addmagMid_r-P2"/>
        </spatial>
        <spatial name="addmagProx_r_tendon" springlength="0.0403241">
            <site site="addmagProx_r-P1"/>
            <!-- <site site ="pelvissite"/> -->
            <!-- <geom geom="AMprox_at_femshaft_r_wrap" sidesite="AMprox_at_femshaft_r_site_addmagProx_r_side"/> -->
            <site site="addmagProx_r-P2"/>
        </spatial>
        <spatial name="bflh_r_tendon" springlength="0.325227">
            <site site="bflh_r-P1"/>
            <site site="bflh_r-P2"/>
            <site site="bflh_r-P3"/>
            <site site = "RightSagittalKneeSite"/>

        </spatial>
        <spatial name="bfsh_r_tendon" springlength="0.105817">
            <site site="bfsh_r-P1"/>
            <!-- <geom geom="BF_at_gastroc_r_wrap" sidesite="BF_at_gastroc_r_site_bfsh_r_side"/> -->
            <site site="bfsh_r-P2"/>
            <site site = "RightSagittalKneeSite"/>

        </spatial>
        <spatial name="edl_r_tendon" springlength="0.368875">
            <site site="edl_r-P1"/>
            <site site="edl_r-P2"/>
            <site site="edl_r-P3"/>
            <site site="edl_r-P4"/>
            <site site="edl_r-P5"/>
            <site site="edl_r-P6"/>
        </spatial>

        <spatial name="ehl_r_tendon" springlength="0.326795">
            <site site="ehl_r-P1"/>
            <site site="ehl_r-P2"/>
            <site site="ehl_r-P3"/>
            <site site="ehl_r-P4"/>
            <site site="ehl_r-P5"/>
            <site site="ehl_r-P6"/>
            <site site="ehl_r-P7"/>
            <site site="ehl_r-P8"/>
        </spatial>
        <spatial name="fdl_r_tendon" springlength="0.378773">
            <site site="fdl_r-P1"/>
            <site site="fdl_r-P2"/>
            <site site="fdl_r-P3"/>
            <site site="fdl_r-P4"/>
            <site site="fdl_r-P5"/>
            <site site="fdl_r-P6"/>
            <site site="fdl_r-P7"/>
            <site site="fdl_r-P8"/>
            <site site ="RightHenkeAnkleSite"/>
        </spatial>
        <spatial name="fhl_r_tendon" springlength="0.35434">
            <site site="fhl_r-P1"/>
            <site site="fhl_r-P2"/>
            <site site="fhl_r-P3"/>
            <site site="fhl_r-P4"/>
            <site site="fhl_r-P5"/>
            <site site="fhl_r-P6"/>
            <site site="fhl_r-P7"/>
            <site site ="RightHenkeAnkleSite"/>
    
        </spatial>
        <spatial name="gaslat_r_tendon" springlength="0.37607">
            <site site="gaslat_r-P1"/>
            <!-- <geom geom="GasLat_at_shank_r_wrap" sidesite="GasLat_at_shank_r_site_gaslat_r_side"/> -->
            <site site="gaslat_r-P2"/>
        </spatial>
        <spatial name="gasmed_r_tendon" springlength="0.398716">
            <site site="gasmed_r-P1"/>
            <!-- <geom geom="GasMed_at_shank_r_wrap" sidesite="GasMed_at_shank_r_site_gasmed_r_side"/> -->
            <site site="gasmed_r-P2"/>
        </spatial>
        <spatial name="glmax1_r_tendon" springlength="0.0488409">
            <site site="glmax1_r-P1"/>
            <site site="glmax1_r-P2"/>
            <geom geom="Gmax1_at_pelvis_r_wrap" sidesite="Gmax1_at_pelvis_r_site_glmax1_r_side"/>
            <site site="glmax1_r-P3"/>
            <site site="glmax1_r-P4"/>
        </spatial>
        <spatial name="glmax2_r_tendon" springlength="0.0678872">
            <site site="glmax2_r-P1"/>
            <site site="glmax2_r-P2"/>
            <!-- <geom geom="Gmax2_at_pelvis_r_wrap" sidesite="Gmax2_at_pelvis_r_site_glmax2_r_side"/> -->
            <site site="glmax2_r-P3"/>
            <site site="glmax2_r-P4"/>
        </spatial>
        <spatial name="glmax3_r_tendon" springlength="0.0697166">
            <site site="glmax3_r-P1"/>
            <site site="glmax3_r-P2"/>
            <!-- <geom geom="Gmax3_at_pelvis_r_wrap" sidesite="Gmax3_at_pelvis_r_site_glmax3_r_side"/> -->
            <site site="glmax3_r-P3"/>
            <site site="glmax3_r-P4"/>
        </spatial>
        <spatial name="glmed1_r_tendon" springlength="0.0558168">
            <site site="glmed1_r-P1"/>
            <site site="glmed1_r-P2"/>
        </spatial>
        <spatial name="glmed2_r_tendon" springlength="0.0652488">
            <site site="glmed2_r-P1"/>
            <site site="glmed2_r-P2"/>
        </spatial>
        <spatial name="glmed3_r_tendon" springlength="0.0452328">
            <site site="glmed3_r-P1"/>
            <site site="glmed3_r-P2"/>
        </spatial>
        <spatial name="glmin1_r_tendon" springlength="0.0161378">
            <site site="glmin1_r-P1"/>
            <site site="glmin1_r-P2"/>
        </spatial>
        <spatial name="glmin2_r_tendon" springlength="0.0260991">
            <site site="glmin2_r-P1"/>
            <site site="glmin2_r-P2"/>
        </spatial>
        <spatial name="glmin3_r_tendon" springlength="0.0508725">
            <site site="glmin3_r-P1"/>
            <site site="glmin3_r-P2"/>
        </spatial>
        <spatial name="grac_r_tendon" springlength="0.172014">
            <site site="grac_r-P1"/>
            <geom geom="GR_at_condyles_r_wrap" sidesite="GR_at_condyles_r_site_grac_r_side"/>
            <site site="grac_r-P2"/>
            <site site="grac_r-P3"/>
        </spatial>
        <spatial name="iliacus_r_tendon" springlength="0.0961207">
            <site site="iliacus_r-P1"/>
            <site site="iliacus_r-P2"/>
            <geom geom="IL_at_brim_r_wrap" sidesite="IL_at_brim_r_site_iliacus_r_side"/>
            <site site="iliacus_r-P3"/>
            <site site="iliacus_r-P4"/>
        </spatial>
        <spatial name="perbrev_r_tendon" springlength="0.147528">
            <site site="perbrev_r-P1"/>
            <site site="perbrev_r-P2"/>
            <site site="perbrev_r-P3"/>
            <site site="perbrev_r-P4"/>
            <site site="perbrev_r-P5"/>
        </spatial>
        <spatial name="perlong_r_tendon" springlength="0.332221">
            <site site="perlong_r-P1"/>
            <site site="perlong_r-P2"/>
            <site site="perlong_r-P3"/>
            <site site="perlong_r-P4"/>
            <site site="perlong_r-P5"/>
            <site site="perlong_r-P6"/>
            <site site="perlong_r-P7"/>
        </spatial>
        <spatial name="piri_r_tendon" springlength="0.114906">
            <site site="piri_r-P1"/>
            <site site="piri_r-P2"/>
            <site site="piri_r-P3"/>
        </spatial>
        <spatial name="psoas_r_tendon" springlength="0.0995432">
            <site site="psoas_r-P1"/>
            <site site="psoas_r-P2"/>
            <!-- <geom geom="PS_at_brim_r_wrap" sidesite="PS_at_brim_r_site_psoas_r_side"/> -->
            <site site="psoas_r-P3"/>
            <site site="psoas_r-P4"/>
        </spatial>
        <spatial name="recfem_r_tendon" springlength="0.448494">
            <site site="recfem_r-P1"/>
            <geom geom="KnExt_at_fem_r_wrap" sidesite="KnExt_at_fem_r_site_recfem_r_side"/>
            <site site="recfem_r-P2"/>
            <site site="recfem_r-P3"/>
            <site site="recfem_r-P4"/>
            <site site="recfem_r-P5"/>
        </spatial>
        <spatial name="sart_r_tendon" springlength="0.124">
            <site site="sart_r-P1"/>
            <site site="sart_r-P2"/>
            <site site="sart_r-P3"/>
            <site site="sart_r-P4"/>
            <site site="sart_r-P5"/>
        </spatial>
        <spatial name="semimem_r_tendon" springlength="0.347586">
            <site site="semimem_r-P1"/>
            <geom geom="SM_at_condyles_r_wrap" sidesite="SM_at_condyles_r_site_semimem_r_side"/>
            <site site="semimem_r-P2"/>
        </spatial>
        <spatial name="semiten_r_tendon" springlength="0.247199">
            <site site="semiten_r-P1"/>
            <geom geom="ST_at_condyles_r_wrap" sidesite="ST_at_condyles_r_site_semiten_r_side"/>
            <site site="semiten_r-P2"/>
            <site site="semiten_r-P3"/>
        </spatial>
        <spatial name="soleus_r_tendon" springlength="0.276756">
            <site site="soleus_r-P1"/>
            <site site="soleus_r-P2"/>
        </spatial>
        <spatial name="tfl_r_tendon" springlength="0.449497">
            <site site="tfl_r-P1"/>
            <site site="tfl_r-P2"/>
            <site site="tfl_r-P3"/>
            <site site="tfl_r-P4"/>
        </spatial>
        <spatial name="tibant_r_tendon" springlength="0.240461">
            <site site="tibant_r-P1"/>
            <site site="tibant_r-P2"/>
            <site site="tibant_r-P3"/>
            <site site="tibant_r-P4"/>
        </spatial>
        <spatial name="tibpost_r_tendon" springlength="0.28078">
            <site site="tibpost_r-P1"/>
            <site site="tibpost_r-P2"/>
            <site site="tibpost_r-P3"/>
            <site site="tibpost_r-P4"/>
        </spatial>
        <spatial name="vasint_r_tendon" springlength="0.202211">
            <site site="vasint_r-P1"/>
            <site site="vasint_r-P2"/>
            <!-- <geom geom ="RightSagittalKneeLink" sidesite = "RightSagittalKneeJoint"> -->
            <!-- <geom geom="KnExt_at_fem_r_wrap" sidesite="KnExt_at_fem_r_site_vasint_r_side"/> --> -->
            <site site="vasint_r-P3"/>
            <site site="vasint_r-P4"/>
            <site site="vasint_r-P5"/>
        </spatial>
        <spatial name="vaslat_r_tendon" springlength="0.220601">
            <site site="vaslat_r-P1"/>
            <site site="vaslat_r-P2"/>
            <geom geom="KnExt_at_fem_r_wrap" sidesite="KnExt_at_fem_r_site_vaslat_r_side"/>
            <site site="vaslat_r-P3"/>
            <site site="vaslat_r-P4"/>
            <site site="vaslat_r-P5"/>
        </spatial>
        <spatial name="vasmed_r_tendon" springlength="0.199904">
            <site site="vasmed_r-P1"/>
            <site site="vasmed_r-P2"/>
            <geom geom="KnExt_at_fem_r_wrap" sidesite="KnExt_at_fem_r_site_vasmed_r_side"/>
            <site site="vasmed_r-P3"/>
            <site site="vasmed_r-P4"/>
            <site site="vasmed_r-P5"/>
        </spatial>
        <spatial name="addbrev_l_tendon" springlength="0.0354503">
            <site site="addbrev_l-P1"/>
            <geom geom="AB_at_femshaft_l_wrap" sidesite="AB_at_femshaft_l_site_addbrev_l_side"/>
            <site site="addbrev_l-P2"/>
        </spatial>
        <spatial name="addlong_l_tendon" springlength="0.131799">
            <site site="addlong_l-P1"/>
            <geom geom="AL_at_femshaft_l_wrap" sidesite="AL_at_femshaft_l_site_addlong_l_side"/>
            <site site="addlong_l-P2"/>
        </spatial>
        <spatial name="addmagDist_l_tendon" springlength="0.0873807">
            <site site="addmagDist_l-P1"/>
            <geom geom="AMdist_at_femshaft_l_wrap" sidesite="AMdist_at_femshaft_l_site_addmagDist_l_side"/>
            <site site="addmagDist_l-P2"/>
        </spatial>
        <spatial name="addmagIsch_l_tendon" springlength="0.216343">
            <site site="addmagIsch_l-P1"/>
            <geom geom="AMisch_at_condyles_l_wrap" sidesite="AMisch_at_condyles_l_site_addmagIsch_l_side"/>
            <site site="addmagIsch_l-P2"/>
        </spatial>
        <spatial name="addmagMid_l_tendon" springlength="0.0466277">
            <site site="addmagMid_l-P1"/>
            <geom geom="AMmid_at_femshaft_l_wrap" sidesite="AMmid_at_femshaft_l_site_addmagMid_l_side"/>
            <site site="addmagMid_l-P2"/>
        </spatial>
        <spatial name="addmagProx_l_tendon" springlength="0.0403241">
            <site site="addmagProx_l-P1"/>
            <geom geom="AMprox_at_femshaft_l_wrap" sidesite="AMprox_at_femshaft_l_site_addmagProx_l_side"/>
            <site site="addmagProx_l-P2"/>
        </spatial>
        <spatial name="bflh_l_tendon" springlength="0.325227">
            <site site="bflh_l-P1"/>
            <site site="bflh_l-P2"/>
            <site site="bflh_l-P3"/>
            <site site = "LeftSagittalKneeSite"/>
        </spatial>
        <spatial name="bfsh_l_tendon" springlength="0.105817">
            <site site="bfsh_l-P1"/>
            <geom geom="BF_at_gastroc_l_wrap" sidesite="BF_at_gastroc_l_site_bfsh_l_side"/>
            <site site="bfsh_l-P2"/>
        </spatial>
        <spatial name="edl_l_tendon" springlength="0.368875">
            <site site="edl_l-P1"/>
            <site site="edl_l-P2"/>
            <site site="edl_l-P3"/>
            <site site="edl_l-P4"/>
            <site site="edl_l-P5"/>
            <site site="edl_l-P6"/>
        </spatial>
        <spatial name="ehl_l_tendon" springlength="0.326795">
            <site site="ehl_l-P1"/>
            <site site="ehl_l-P2"/>
            <site site="ehl_l-P3"/>
            <site site="ehl_l-P4"/>
            <site site="ehl_l-P5"/>
            <site site="ehl_l-P6"/>
            <site site="ehl_l-P7"/>
            <site site="ehl_l-P8"/>
        </spatial>
        <spatial name="fdl_l_tendon" springlength="0.378773">
            <site site="fdl_l-P1"/>
            <site site="fdl_l-P2"/>
            <site site="fdl_l-P3"/>
            <site site="fdl_l-P4"/>
            <site site="fdl_l-P5"/>
            <site site="fdl_l-P6"/>
            <site site="fdl_l-P7"/>
            <site site="fdl_l-P8"/>
            <site site ="LeftHenkeAnkleSite"/>

        </spatial>
        <spatial name="fhl_l_tendon" springlength="0.35434">
            <site site="fhl_l-P1"/>
            <site site="fhl_l-P2"/>
            <site site="fhl_l-P3"/>
            <site site="fhl_l-P4"/>
            <site site="fhl_l-P5"/>
            <site site="fhl_l-P6"/>
            <site site="fhl_l-P7"/>
            <site site ="LeftHenkeAnkleSite"/>

        </spatial>
        <spatial name="gaslat_l_tendon" springlength="0.37607">
            <site site="gaslat_l-P1"/>
            <geom geom="GasLat_at_shank_l_wrap" sidesite="GasLat_at_shank_l_site_gaslat_l_side"/>
            <site site="gaslat_l-P2"/>
        </spatial>
        <spatial name="gasmed_l_tendon" springlength="0.398716">
            <site site="gasmed_l-P1"/>
            <geom geom="GasMed_at_shank_l_wrap" sidesite="GasMed_at_shank_l_site_gasmed_l_side"/>
            <site site="gasmed_l-P2"/>
        </spatial>
        <spatial name="glmax1_l_tendon" springlength="0.0488409">
            <site site="glmax1_l-P1"/>
            <site site="glmax1_l-P2"/>
            <!-- <geom geom="Gmax1_at_pelvis_l_wrap" sidesite="Gmax1_at_pelvis_l_site_glmax1_l_side"/> -->
            <site site="glmax1_l-P3"/>
            <site site="glmax1_l-P4"/>
        </spatial>
        <spatial name="glmax2_l_tendon" springlength="0.0678872">
            <site site="glmax2_l-P1"/>
            <site site="glmax2_l-P2"/>
            <!-- <geom geom="Gmax2_at_pelvis_l_wrap" sidesite="Gmax2_at_pelvis_l_site_glmax2_l_side"/> -->
            <site site="glmax2_l-P3"/>
            <site site="glmax2_l-P4"/>
        </spatial>
        <spatial name="glmax3_l_tendon" springlength="0.0697166">
            <site site="glmax3_l-P1"/>
            <site site="glmax3_l-P2"/>
            <geom geom="Gmax3_at_pelvis_l_wrap" sidesite="Gmax3_at_pelvis_l_site_glmax3_l_side"/>
            <site site="glmax3_l-P3"/>
            <site site="glmax3_l-P4"/>
        </spatial>
        <spatial name="glmed1_l_tendon" springlength="0.0558168">
            <site site="glmed1_l-P1"/>
            <site site="glmed1_l-P2"/>
        </spatial>
        <spatial name="glmed2_l_tendon" springlength="0.0652488">
            <site site="glmed2_l-P1"/>
            <site site="glmed2_l-P2"/>
        </spatial>
        <spatial name="glmed3_l_tendon" springlength="0.0452328">
            <site site="glmed3_l-P1"/>
            <site site="glmed3_l-P2"/>
        </spatial>
        <spatial name="glmin1_l_tendon" springlength="0.0161378">
            <site site="glmin1_l-P1"/>
            <site site="glmin1_l-P2"/>
        </spatial>
        <spatial name="glmin2_l_tendon" springlength="0.0260991">
            <site site="glmin2_l-P1"/>
            <site site="glmin2_l-P2"/>
        </spatial>
        <spatial name="glmin3_l_tendon" springlength="0.0508725">
            <site site="glmin3_l-P1"/>
            <site site="glmin3_l-P2"/>
        </spatial>
        <spatial name="grac_l_tendon" springlength="0.172014">
            <site site="grac_l-P1"/>
            <geom geom="GR_at_condyles_l_wrap" sidesite="GR_at_condyles_l_site_grac_l_side"/>
            <site site="grac_l-P2"/>
            <site site="grac_l-P3"/>
        </spatial>
        <spatial name="iliacus_l_tendon" springlength="0.0961207">
            <site site="iliacus_l-P1"/>
            <site site="iliacus_l-P2"/>
            <geom geom="IL_at_brim_l_wrap" sidesite="IL_at_brim_l_site_iliacus_l_side"/>
            <site site="iliacus_l-P3"/>
            <site site="iliacus_l-P4"/>
        </spatial>
        <spatial name="perbrev_l_tendon" springlength="0.147528">
            <site site="perbrev_l-P1"/>
            <site site="perbrev_l-P2"/>
            <site site="perbrev_l-P3"/>
            <site site="perbrev_l-P4"/>
            <site site="perbrev_l-P5"/>
        </spatial>
        <spatial name="perlong_l_tendon" springlength="0.332221">
            <site site="perlong_l-P1"/>
            <site site="perlong_l-P2"/>
            <site site="perlong_l-P3"/>
            <site site="perlong_l-P4"/>
            <site site="perlong_l-P5"/>
            <site site="perlong_l-P6"/>
            <site site="perlong_l-P7"/>
        </spatial>
        <spatial name="piri_l_tendon" springlength="0.114906">
            <site site="piri_l-P1"/>
            <site site="piri_l-P2"/>
            <site site="piri_l-P3"/>
        </spatial>
        <spatial name="psoas_l_tendon" springlength="0.0995432">
            <site site="psoas_l-P1"/>
            <site site="psoas_l-P2"/>
            <!-- <geom geom="PS_at_brim_l_wrap" sidesite="PS_at_brim_l_site_psoas_l_side"/> -->
            <site site="psoas_l-P3"/>
            <site site="psoas_l-P4"/>
        </spatial>
        <spatial name="recfem_l_tendon" springlength="0.448494">
            <site site="recfem_l-P1"/>
            <geom geom="KnExt_at_fem_l_wrap" sidesite="KnExt_at_fem_l_site_recfem_l_side"/>
            <site site="recfem_l-P2"/>
            <site site="recfem_l-P3"/>
            <site site="recfem_l-P4"/>
            <site site="recfem_l-P5"/>
        </spatial>
        <spatial name="sart_l_tendon" springlength="0.124">
            <site site="sart_l-P1"/>
            <site site="sart_l-P2"/>
            <site site="sart_l-P3"/>
            <site site="sart_l-P4"/>
            <site site="sart_l-P5"/>
        </spatial>
        <spatial name="semimem_l_tendon" springlength="0.347586">
            <site site="semimem_l-P1"/>
            <geom geom="SM_at_condyles_l_wrap" sidesite="SM_at_condyles_l_site_semimem_l_side"/>
            <site site="semimem_l-P2"/>
        </spatial>
        <spatial name="semiten_l_tendon" springlength="0.247199">
            <site site="semiten_l-P1"/>
            <geom geom="ST_at_condyles_l_wrap" sidesite="ST_at_condyles_l_site_semiten_l_side"/>
            <site site="semiten_l-P2"/>
            <site site="semiten_l-P3"/>
        </spatial>
        <spatial name="soleus_l_tendon" springlength="0.276756">
            <site site="soleus_l-P1"/>
            <site site="soleus_l-P2"/>
        </spatial>
        <spatial name="tfl_l_tendon" springlength="0.449497">
            <site site="tfl_l-P1"/>
            <site site="tfl_l-P2"/>
            <site site="tfl_l-P3"/>
            <site site="tfl_l-P4"/>
        </spatial>
        <spatial name="tibant_l_tendon" springlength="0.240461">
            <site site="tibant_l-P1"/>
            <site site="tibant_l-P2"/>
            <site site="tibant_l-P3"/>
            <site site="tibant_l-P4"/>
        </spatial>
        <spatial name="tibpost_l_tendon" springlength="0.28078">
            <site site="tibpost_l-P1"/>
            <site site="tibpost_l-P2"/>
            <site site="tibpost_l-P3"/>
            <site site="tibpost_l-P4"/>
        </spatial>
        <spatial name="vasint_l_tendon" springlength="0.202211">
            <site site="vasint_l-P1"/>
            <site site="vasint_l-P2"/>
            <geom geom="KnExt_at_fem_l_wrap" sidesite="KnExt_at_fem_l_site_vasint_l_side"/>
            <site site="vasint_l-P3"/>
            <site site="vasint_l-P4"/>
            <site site="vasint_l-P5"/>
        </spatial>
        <spatial name="vaslat_l_tendon" springlength="0.220601">
            <site site="vaslat_l-P1"/>
            <site site="vaslat_l-P2"/>
            <geom geom="KnExt_at_fem_l_wrap" sidesite="KnExt_at_fem_l_site_vaslat_l_side"/>
            <site site="vaslat_l-P3"/>
            <site site="vaslat_l-P4"/>
            <site site="vaslat_l-P5"/>
        </spatial>
        <spatial name="vasmed_l_tendon" springlength="0.199904">
            <site site="vasmed_l-P1"/>
            <site site="vasmed_l-P2"/>
            <!-- <geom geom="KnExt_at_fem_l_wrap" sidesite="KnExt_at_fem_l_site_vasmed_l_side"/> -->
            <site site="vasmed_l-P3"/>
            <site site="vasmed_l-P4"/>
            <site site="vasmed_l-P5"/>
        </spatial>
    </tendon>
        
    <contact>
        <pair condim="3" friction="1 1 0.005 0.0001 0.0001" geom1="left_sole" geom2="terrain_mesh" margin="0.0001"/>
        <pair condim="3" friction="1 1 0.005 0.0001 0.0001" geom1="right_sole" geom2="terrain_mesh" margin="0.0001"/>
    </contact>

 <!-- Actuators -->
    <actuator>
        <general ctrllimited="true" ctrlrange="-350 350" joint="LeftFrontalHipJoint" class="multi_mode_controlled_actuator" name="LeftFrontalHipLink_actuator"/>
        <general ctrllimited="true" ctrlrange="-180 180" joint="LeftTransverseHipJoint" class="multi_mode_controlled_actuator" name="LeftTransverseHipLink_actuator"/>
        <general ctrllimited="true" ctrlrange="-219 219" joint="LeftSagittalHipJoint" class="multi_mode_controlled_actuator" name="LeftSagittalHipLink_actuator"/>
        <general ctrllimited="true" ctrlrange="-219 219" joint="LeftSagittalKneeJoint" class="multi_mode_controlled_actuator" name="LeftSagittalKneeLink_actuator"/>
        <general ctrllimited="true" ctrlrange="-184 184" joint="LeftSagittalAnkleJoint" class="multi_mode_controlled_actuator" name="LeftSagittalAnkleLink_actuator"/>
        <general ctrllimited="true" ctrlrange="-82 82" joint="LeftHenkeAnkleJoint" class="multi_mode_controlled_actuator" name="LeftHenkeAnkleLink_actuator"/>
        <general ctrllimited="true" ctrlrange="-350 350" joint="RightFrontalHipJoint" class="multi_mode_controlled_actuator" name="RightFrontalHipLink_actuator"/>
        <general ctrllimited="true" ctrlrange="-180 180" joint="RightTransverseHipJoint" class="multi_mode_controlled_actuator" name="RightTransverseHipLink_actuator"/>
        <general ctrllimited="true" ctrlrange="-219 219" joint="RightSagittalHipJoint" class="multi_mode_controlled_actuator" name="RightSagittalHipLink_actuator"/>
        <general ctrllimited="true" ctrlrange="-219 219" joint="RightSagittalKneeJoint" class="multi_mode_controlled_actuator" name="RightSagittalKneeLink_actuator"/>
        <general ctrllimited="true" ctrlrange="-184 184" joint="RightSagittalAnkleJoint" class="multi_mode_controlled_actuator" name="RightSagittalAnkleLink_actuator"/>
        <general ctrllimited="true" ctrlrange="-82 82" joint="RightHenkeAnkleJoint" class="multi_mode_controlled_actuator" name="RightHenkeAnkleLink_actuator"/>
    </actuator>

<!-- Sensors -->
    <sensor>
        <touch name="opto1" site="opto1"/>
        <touch name="opto2" site="opto2"/>
        <touch name="opto3" site="opto3"/>
        <touch name="opto4" site="opto4"/>
        <touch name="opto5" site="opto5"/>
        <touch name="opto6" site="opto6"/>
        <touch name="opto7" site="opto7"/>
        <touch name="opto8" site="opto8"/>
        <framequat name="pelvis-orientation" objname="pelvis_imu" objtype="site"/>
        <gyro name="pelvis-angular-velocity" noise="5e-4" site="pelvis_imu"/>
        <accelerometer name="pelvis-linear-acceleration" noise="1e-2" site="pelvis_imu"/>
        <framequat name="thorax-orientation" objname="thorax_imu" objtype="site"/>
        <gyro name="thorax-angular-velocity" noise="5e-4" site="thorax_imu"/>
        <accelerometer name="thorax-linear-acceleration" noise="1e-2" site="thorax_imu"/>
        <framequat name="left_tibia-orientation" objname="left_tibia_imu" objtype="site"/>
        <gyro name="left_tibia-angular-velocity" noise="5e-4" site="left_tibia_imu"/>
        <accelerometer name="left_tibia-linear-acceleration" noise="1e-2" site="left_tibia_imu"/>
        <framequat name="right_tibia-orientation" objname="right_tibia_imu" objtype="site"/>
        <gyro name="right_tibia-angular-velocity" noise="5e-4" site="right_tibia_imu"/>
        <accelerometer name="right_tibia-linear-acceleration" noise="1e-2" site="right_tibia_imu"/>
        <framequat name="left_foot-orientation" objname="left_foot_imu" objtype="site"/>
        <gyro name="left_foot-angular-velocity" noise="5e-4" site="left_foot_imu"/>
        <accelerometer name="left_foot-linear-acceleration" noise="1e-2" site="left_foot_imu"/>
        <framequat name="right_foot-orientation" objname="right_foot_imu" objtype="site"/>
        <gyro name="right_foot-angular-velocity" noise="5e-4" site="right_foot_imu"/>
        <accelerometer name="right_foot-linear-acceleration" noise="1e-2" site="right_foot_imu"/>
    </sensor>
</mujoco>